Workbook

Sheet Briefing_FID
A1: Portfolio | B1: Estratégia | C1: Elegibilidade | D1: Oi Vende | E1: Canais | AM1: Campanha | AP1: Data | AR1: Configurações da Campanha | AY1: Regras de Campanha | BB1: Configurações da Oferta | BE1: ="Preço Fixo "&DOLLAR(ARBOR!C2,2) -> Preço Fixo R$ 75,84 | BH1: ="Oi TV Start HD (PCS-OzTL40) "&DOLLAR(VLOOKUP("PCS-OzTL40",ARBOR!$A:$C,3,0),2) -> Oi TV Start HD (PCS-OzTL40) R$ 99,00 | BK1: ="Oi TV Mix HD (PCS-OzTL41) "&DOLLAR(VLOOKUP("PCS-OzTL41",ARBOR!$A:$C,3,0),2) -> Oi TV Mix HD (PCS-OzTL41) R$ 121,03 | BN1: ="Oi TV Mix HBO Max HD (PCS-OzTL44) "&DOLLAR(VLOOKUP("PCS-OzTL44",ARBOR!$A:$C,3,0),2) -> Oi TV Mix HBO Max HD (PCS-OzTL44) R$ 192,61 | BQ1: ="Oi TV Mix Telecine HD (PCS-OzTL43) "&DOLLAR(VLOOKUP("PCS-OzTL43",ARBOR!$A:$C,3,0),2) -> Oi TV Mix Telecine HD (PCS-OzTL43) R$ 203,63 | BT1: ="Oi TV Mix Cinema HD (PCS-OzTL45) "&DOLLAR(VLOOKUP("PCS-OzTL45",ARBOR!$A:$C,3,0),2) -> Oi TV Mix Cinema HD (PCS-OzTL45) R$ 209,13 | BW1: ="Oi TV Mix HD DVR (PCS-OzTL741) "&DOLLAR(VLOOKUP("PCS-OzTL741",ARBOR!$A:$C,3,0),2) -> Oi TV Mix HD DVR (PCS-OzTL741) R$ 176,09 | BZ1: ="Oi TV Mix HBOMax HD DVR (PCS-OzTL744) "&DOLLAR(VLOOKUP("PCS-OzTL744",ARBOR!$A:$C,3,0),2) -> Oi TV Mix HBOMax HD DVR (PCS-OzTL744) R$ 209,13 | CC1: ="Oi TV Mix Telecine HD DVR (PCS-OzTL743) "&DOLLAR(VLOOKUP("PCS-OzTL743",ARBOR!$A:$C,3,0),2) -> Oi TV Mix Telecine HD DVR (PCS-OzTL743) R$ 220,14 | CF1: ="Oi TV Mix Cinema HD DVR (PCS-OzTL745) "&DOLLAR(VLOOKUP("PCS-OzTL745",ARBOR!$A:$C,3,0),2) -> Oi TV Mix Cinema HD DVR (PCS-OzTL745) R$ 253,18 | CI1: ="Oi TV Total HD (PCS-OzTL42) "&DOLLAR(VLOOKUP("PCS-OzTL42",ARBOR!$A:$C,3,0),2) -> Oi TV Total HD (PCS-OzTL42) R$ 165,08 | CL1: ="Oi TV Total HBO Max HD (PCS-OzTL47) "&DOLLAR(VLOOKUP("PCS-OzTL47",ARBOR!$A:$C,3,0),2) -> Oi TV Total HBO Max HD (PCS-OzTL47) R$ 203,63 | CO1: ="Oi TV Total Telecine HD (PCS-OzTL46) "&DOLLAR(VLOOKUP("PCS-OzTL46",ARBOR!$A:$C,3,0),2) -> Oi TV Total Telecine HD (PCS-OzTL46) R$ 214,64 | CR1: ="Oi TV Total Cinema HD (PCS-OzTL48) "&DOLLAR(VLOOKUP("PCS-OzTL48",ARBOR!$A:$C,3,0),2) -> Oi TV Total Cinema HD (PCS-OzTL48) R$ 253,18 | CU1: ="Oi TV Total HD DVR (PCS-OzTL742) "&DOLLAR(VLOOKUP("PCS-OzTL742",ARBOR!$A:$C,3,0),2) -> Oi TV Total HD DVR (PCS-OzTL742) R$ 220,14 | CX1: ="Oi TV Total HBOMax HD DVR (PCS-OzTL747) "&DOLLAR(VLOOKUP("PCS-OzTL747",ARBOR!$A:$C,3,0),2) -> Oi TV Total HBOMax HD DVR (PCS-OzTL747) R$ 258,69 | DA1: ="Oi TV Total Telecine HD DVR (PCS-OzTL746) "&DOLLAR(VLOOKUP("PCS-OzTL746",ARBOR!$A:$C,3,0),2) -> Oi TV Total Telecine HD DVR (PCS-OzTL746) R$ 269,70 | DD1: ="Oi TV Total Cinema HD DVR (PCS-OzTL748) "&DOLLAR(VLOOKUP("PCS-OzTL748",ARBOR!$A:$C,3,0),2) -> Oi TV Total Cinema HD DVR (PCS-OzTL748) R$ 308,25 | DG1: ="Oi TV Combate (PCS-OzTL34) "&DOLLAR(VLOOKUP("PCS-OzTL34",ARBOR!$A:$C,3,0),2) -> Oi TV Combate (PCS-OzTL34) R$ 110,13 | DJ1: ="Oi TV Sexy Hot (PCS-OzTL31) "&DOLLAR(VLOOKUP("PCS-OzTL31",ARBOR!$A:$C,3,0),2) -> Oi TV Sexy Hot (PCS-OzTL31) R$ 21,91 | DM1: ="Oi TV Playboy (PCS-OzTL32) "&DOLLAR(VLOOKUP("PCS-OzTL32",ARBOR!$A:$C,3,0),2) -> Oi TV Playboy (PCS-OzTL32) R$ 21,91 | DP1: ="Oi TV Sexy Hot + Playboy (PCS-OzTL33) "&DOLLAR(VLOOKUP("PCS-OzTL33",ARBOR!$A:$C,3,0),2) -> Oi TV Sexy Hot + Playboy (PCS-OzTL33) R$ 32,92 | DS1: ="Oi TV SexPrivê (PCS-OzTL503) "&DOLLAR(VLOOKUP("PCS-OzTL503",ARBOR!$A:$C,3,0),2) -> Oi TV SexPrivê (PCS-OzTL503) R$ 16,40 | DV1: ="Oi TV Étnicos (PCS-OzTL500) "&DOLLAR(VLOOKUP("PCS-OzTL500",ARBOR!$A:$C,3,0),2) -> Oi TV Étnicos (PCS-OzTL500) R$ 11,01 | DY1: ="Coleção OI (PCS-OzTL50)" -> Coleção OI (PCS-OzTL50) | EB1: ="Fox Premium (PCS-OzTL51)" -> Fox Premium (PCS-OzTL51) | EE1: ="PenVr (PCS-OzTL52)" -> PenVr (PCS-OzTL52) | EH1: ="PFC Completo (PCS-OzTL53)" -> PFC Completo (PCS-OzTL53) | EK1: ="PFC Básico (PCS-OzTL54)" -> PFC Básico (PCS-OzTL54) | EN1: ="Oi TV Ponto Adicional (PCS-OzTL99) "&DOLLAR(VLOOKUP("PCS-OzTL99",ARBOR!$A:$C,3,0),2) -> Oi TV Ponto Adicional (PCS-OzTL99) R$ 29,90 | ES1: Multa | EZ1: Benefícios de Minutos/SMS | FC1: Benefícios de Minutos/SMS | FF1: Chip Alone | FG1: TOTAIS | FX1: Campos de uso livre
A2: Portfolio (linguagem comercial) | B2: Estratégia (aquisição, retenção ou Oi Pontos) | C2: Cliente Elegivel | D2: Visível no Oi Vende? | E2: Oi BSIM R1 | F2: Oi BSIM R2 | G2: Atendimento | H2: BO Atendimento | I2: Ouvidoria | J2: Auditoria de Vendas | K2: BO Contratos | L2: Hotline | M2: BO Hotline | N2: Faranqua Alto Valor | O2: Franquia Oi Atende | P2: Agex | Q2: Agex Simples | R2: Lojas Próprias | S2: Pap | T2: Televendas Ativo 3P RES | U2: Televendas Ativo 4P/ 3P Móvel | V2: Televendas Receptivo 3P RES | W2: Televendas Receptivo 4P/ 3P MÓVEL | X2: Teleagentes | Y2: Teleagentes 4P | Z2: Web | AA2: Retenção | AB2: BO Retenção | AC2: Blindagem Oi ToTal | AD2: Blindagem | AE2: Ilha de Migração | AF2: Rentabilização | AG2: Procon | AH2: JEC | AI2: BO Oi Pontos | AK2: Operações Especiais Retenção (Propenso e Ativo Reversão) | AL2: PDV's específicos | AM2: Nome da campanha | AN2: Objetivo da Campanha | AO2: Resumo da Campanha | AP2: Data inicio | AQ2: Data fim | AR2: Localidade | AS2: Filial | AT2: DDD's | AU2: Unidade de Negócio | AV2: nº Maximo de oportunidades | AW2: Nº de adesões esperadas | AX2: Publico Alvo | AY2: Campanha Subsidiada | AZ2: DACC | BA2: CSP | BB2: Nome Oferta | BC2: Plano Voz (campo obrigatório) | BD2: Código SBL | BE2: Comercial | BF2: % Desc Ajust | BG2: Código | BH2: Comercial | BI2: % Desc (ind) | BJ2: Código | BK2: Comercial | BL2: % Desc (ind) | BM2: Código | BN2: Comercial | BO2: % Desc (ind) | BP2: Código | BQ2: Comercial | BR2: % Desc (ind) | BS2: Código | BT2: Comercial | BU2: % Desc (ind) | BV2: Código | BW2: Comercial | BX2: % Desc (ind) | BY2: Código | BZ2: Comercial | CA2: % Desc (ind) | CB2: Código | CC2: Comercial | CD2: % Desc (ind) | CE2: Código | CF2: Comercial | CG2: % Desc (ind) | CH2: Código | CI2: Comercial | CJ2: % Desc (ind) | CK2: Código | CL2: Comercial | CM2: % Desc (ind) | CN2: Código | CO2: Comercial | CP2: % Desc (ind) | CQ2: Código | CR2: Comercial | CS2: % Desc (ind) | CT2: Código | CU2: Comercial | CV2: % Desc (ind) | CW2: Código | CX2: Comercial | CY2: % Desc (ind) | CZ2: Código | DA2: Comercial | DB2: % Desc (ind) | DC2: Código | DD2: Comercial | DE2: % Desc (ind) | DF2: Código | DG2: Comercial | DH2: % Desc | DI2: Cod | DJ2: Comercial | DK2: % Desc | DL2: Cod | DM2: Comercial | DN2: % Desc | DO2: Cod | DP2: Comercial | DQ2: % Desc | DR2: Cod | DS2: Comercial | DT2: % Desc | DU2: Cod | DV2: Comercial | DW2: % Desc | DX2: Cod | DY2: Comercial | DZ2: % Desc | EA2: Código | EB2: Comercial | EC2: % Desc | ED2: Código | EE2: Comercial | EF2: % Desc | EG2: Código | EH2: Comercial | EI2: % Desc | EJ2: Código | EK2: Comercial | EL2: % Desc | EM2: Código | EN2: Comercial | EO2: % Desc | EP2: Cod | EQ2: 1o Ponto Adicional Gratuito? | ER2: Cod | ES2: Sim/ Não | ET2: Tipo Benefício/ Aparelho/ Oi Pontos | EU2: Valor da multa | EV2: Duração (meses) | EW2: Benefício que gerou a fidelização | EX2: Código Benefício que gerou Fidelização | EY2: ELEMENTO DE MULTA | EZ2: Tipo do benefício | FA2: Nome do benefício | FB2: Código | FC2: Tipo do benefício | FD2: Nome do benefício | FE2: Código | FF2: Elementos | FG2: [Fixo] START | FH2: [Fixo] MIX | FI2: [Fixo] MIX HBO | FJ2: [Fixo] MIX Telecine | FK2: [Fixo] MIX Cinema | FL2: [Fixo] MIX DVR | FM2: [Fixo] MIX HBO DVR | FN2: [Fixo] MIX Telecine DVR | FO2: [Fixo] MIX Cinema DVR | FP2: [Fixo] Total | FQ2: [Fixo] Total HBO | FR2: [Fixo] Total Telecine | FS2: [Fixo] Total Cinema | FT2: [Fixo] Total DVR | FU2: [Fixo] Total HBO DVR | FV2: [Fixo] Total Telecine DVR | FW2: [Fixo] Total Cinema DVR | FX2: Livre 1 | FY2: Livre 2 | FZ2: Livre 3 | GA2: Livre 4 | GB2: Livre 5 | GC2: Livre 6 | GD2: Livre 7 | GE2: Livre 8 | GF2: Livre 9 | GG2: Livre 10
A3: Oi Total | B3: Migração | C3: Atuais | D3: Não | AM3: OT_ATV_JUL17_FID_DACC_2PTV_TV1_ST_LD-VC_OF1 | AN3: Rentabilizar atuais clientes do plano | AO3: Produto Fixo + TV , Produto com fidelização | AP3: 42917 | AQ3: 43039 | AR3: 20. Oi Total | AS3: 20. Oi Total | AU3: Varejo | AV3: 20 | AW3: 10000 | AX3: Campanha Restrita | AY3: Sim | AZ3: Sim | BA3: Não | BB3: OT_ATV_JUL17_FID_DACC_2PTV_TV1_ST_LD-VC_OF1 | BC3: Oi Total Fixo + TV 1 | BD3: =IF(BC3="Oi Total Fixo + TV 1","CFG-2Plowpi",IF(BC3="Oi Total Fixo + TV 2","PCS-2PMepi",IF(BC3="Oi Total Fixo + TV 3","PCS-2PHipi",""))) -> CFG-2Plowpi | BE3: 60 | BF3: =IF(BE3=0,"",IF(BE3=VLOOKUP("FIXO",ARBOR!$A:$C,3,0),0.0001,IF(BE3>VLOOKUP("FIXO",ARBOR!$A:$C,3,0),"Maior que CAP!",IF((DOLLAR(BE3+(VLOOKUP("FIXO",ARBOR!$A:$C,3,0)*-TRUNC(BE3/VLOOKUP("FIXO",ARBOR!$A:$C,3,0)-1,4)),6))<>(DOLLAR(VLOOKUP("FIXO",ARBOR!$A:$C,3,0),6)),-TRUNC(BE3/VLOOKUP("FIXO",ARBOR!$A:$C,3,0)-1,4)+0.0001,-TRUNC(BE3/VLOOKUP("FIXO",ARBOR!$A:$C,3,0)-1,4))))) -> 0.2089 | BG3: =IF(ISERROR(IF(BF3="","",VLOOKUP(($BC3&BF3&"Template de desconto FLAT bundle - Fixo - Varejo - Ganho Tributário Cross"),BENEFICIOS!$A:$G,5,0))),"Criar",IF(BF3="","",VLOOKUP(($BC3&BF3&"Template de desconto FLAT bundle - Fixo - Varejo - Ganho Tributário Cross"),BENEFICIOS!$A:$G,5,0))) -> Criar | BH3: 74.9 | BI3: =IF(BH3=0,"",IF(BH3=VLOOKUP("PCS-OzTL40",ARBOR!$A:$C,3,0),0.0001,IF(BH3>VLOOKUP("PCS-OzTL40",ARBOR!$A:$C,3,0),"Maior que CAP!",IF((DOLLAR(BH3+(VLOOKUP("PCS-OzTL40",ARBOR!$A:$C,3,0)*-TRUNC(BH3/VLOOKUP("PCS-OzTL40",ARBOR!$A:$C,3,0)-1,4)),6))<>(DOLLAR(VLOOKUP("PCS-OzTL40",ARBOR!$A:$C,3,0),6)),-TRUNC(BH3/VLOOKUP("PCS-OzTL40",ARBOR!$A:$C,3,0)-1,4)+0.0001,-TRUNC(BH3/VLOOKUP("PCS-OzTL40",ARBOR!$A:$C,3,0)-1,4))))) -> 0.2435 | BJ3: =IF(ISERROR(IF(BI3="","",VLOOKUP((BC3&BI3&"Template desconto FLAT Plano Principal Oi TV nível conta"),BENEFICIOS!$A:$G,5,0))),"Criar",IF(BI3="","",VLOOKUP((BC3&BI3&"Template desconto FLAT Plano Principal Oi TV nível conta"),BENEFICIOS!$A:$G,5,0))) -> Criar | BL3: =IF(BK3=0,"",IF(BK3=VLOOKUP("PCS-OzTL41",ARBOR!$A:$C,3,0),0.0001,IF(BK3>VLOOKUP("PCS-OzTL41",ARBOR!$A:$C,3,0),"Maior que CAP!",IF((DOLLAR(BK3+(VLOOKUP("PCS-OzTL41",ARBOR!$A:$C,3,0)*-TRUNC(BK3/VLOOKUP("PCS-OzTL41",ARBOR!$A:$C,3,0)-1,4)),6))<>(DOLLAR(VLOOKUP("PCS-OzTL41",ARBOR!$A:$C,3,0),6)),-TRUNC(BK3/VLOOKUP("PCS-OzTL41",ARBOR!$A:$C,3,0)-1,4)+0.0001,-TRUNC(BK3/VLOOKUP("PCS-OzTL41",ARBOR!$A:$C,3,0)-1,4))))) | BM3: =IF(ISERROR(IF(BL3="","",VLOOKUP((BC3&BL3&"Template desconto FLAT Plano Principal Oi TV nível conta"),BENEFICIOS!$A:$G,5,0))),"Criar",IF(BL3="","",VLOOKUP((BC3&BL3&"Template desconto FLAT Plano Principal Oi TV nível conta"),BENEFICIOS!$A:$G,5,0))) | BO3: =IF(BN3=0,"",IF(BN3=VLOOKUP("PCS-OzTL44",ARBOR!$A:$C,3,0),0.0001,IF(BN3>VLOOKUP("PCS-OzTL44",ARBOR!$A:$C,3,0),"Maior que CAP!",IF((DOLLAR(BN3+(VLOOKUP("PCS-OzTL44",ARBOR!$A:$C,3,0)*-TRUNC(BN3/VLOOKUP("PCS-OzTL44",ARBOR!$A:$C,3,0)-1,4)),6))<>(DOLLAR(VLOOKUP("PCS-OzTL44",ARBOR!$A:$C,3,0),6)),-TRUNC(BN3/VLOOKUP("PCS-OzTL44",ARBOR!$A:$C,3,0)-1,4)+0.0001,-TRUNC(BN3/VLOOKUP("PCS-OzTL44",ARBOR!$A:$C,3,0)-1,4))))) | BP3: =IF(ISERROR(IF(BO3="","",VLOOKUP((BC3&BO3&"Template desconto FLAT Plano Principal Oi TV nível conta"),BENEFICIOS!$A:$G,5,0))),"Criar",IF(BO3="","",VLOOKUP((BC3&BO3&"Template desconto FLAT Plano Principal Oi TV nível conta"),BENEFICIOS!$A:$G,5,0))) | BR3: =IF(BQ3=0,"",IF(BQ3=VLOOKUP("PCS-OzTL43",ARBOR!$A:$C,3,0),0.0001,IF(BQ3>VLOOKUP("PCS-OzTL43",ARBOR!$A:$C,3,0),"Maior que CAP!",IF((DOLLAR(BQ3+(VLOOKUP("PCS-OzTL43",ARBOR!$A:$C,3,0)*-TRUNC(BQ3/VLOOKUP("PCS-OzTL43",ARBOR!$A:$C,3,0)-1,4)),6))<>(DOLLAR(VLOOKUP("PCS-OzTL43",ARBOR!$A:$C,3,0),6)),-TRUNC(BQ3/VLOOKUP("PCS-OzTL43",ARBOR!$A:$C,3,0)-1,4)+0.0001,-TRUNC(BQ3/VLOOKUP("PCS-OzTL43",ARBOR!$A:$C,3,0)-1,4))))) | BS3: =IF(ISERROR(IF(BR3="","",VLOOKUP((BC3&BR3&"Template desconto FLAT Plano Principal Oi TV nível conta"),BENEFICIOS!$A:$G,5,0))),"Criar",IF(BR3="","",VLOOKUP((BC3&BR3&"Template desconto FLAT Plano Principal Oi TV nível conta"),BENEFICIOS!$A:$G,5,0))) | BU3: =IF(BT3=0,"",IF(BT3=VLOOKUP("PCS-OzTL45",ARBOR!$A:$C,3,0),0.0001,IF(BT3>VLOOKUP("PCS-OzTL45",ARBOR!$A:$C,3,0),"Maior que CAP!",IF((DOLLAR(BT3+(VLOOKUP("PCS-OzTL45",ARBOR!$A:$C,3,0)*-TRUNC(BT3/VLOOKUP("PCS-OzTL45",ARBOR!$A:$C,3,0)-1,4)),6))<>(DOLLAR(VLOOKUP("PCS-OzTL45",ARBOR!$A:$C,3,0),6)),-TRUNC(BT3/VLOOKUP("PCS-OzTL45",ARBOR!$A:$C,3,0)-1,4)+0.0001,-TRUNC(BT3/VLOOKUP("PCS-OzTL45",ARBOR!$A:$C,3,0)-1,4))))) | BV3: =IF(ISERROR(IF(BU3="","",VLOOKUP((BC3&BU3&"Template desconto FLAT Plano Principal Oi TV nível conta"),BENEFICIOS!$A:$G,5,0))),"Criar",IF(BU3="","",VLOOKUP((BC3&BU3&"Template desconto FLAT Plano Principal Oi TV nível conta"),BENEFICIOS!$A:$G,5,0))) | BX3: =IF(BW3=0,"",IF(BW3=VLOOKUP("PCS-OzTL741",ARBOR!$A:$C,3,0),0.0001,IF(BW3>VLOOKUP("PCS-OzTL741",ARBOR!$A:$C,3,0),"Maior que CAP!",IF((DOLLAR(BW3+(VLOOKUP("PCS-OzTL741",ARBOR!$A:$C,3,0)*-TRUNC(BW3/VLOOKUP("PCS-OzTL741",ARBOR!$A:$C,3,0)-1,4)),6))<>(DOLLAR(VLOOKUP("PCS-OzTL741",ARBOR!$A:$C,3,0),6)),-TRUNC(BW3/VLOOKUP("PCS-OzTL741",ARBOR!$A:$C,3,0)-1,4)+0.0001,-TRUNC(BW3/VLOOKUP("PCS-OzTL741",ARBOR!$A:$C,3,0)-1,4))))) | BY3: =IF(ISERROR(IF(BX3="","",VLOOKUP((BC3&BX3&"Template desconto FLAT Plano Principal Oi TV nível conta"),BENEFICIOS!$A:$G,5,0))),"Criar",IF(BX3="","",VLOOKUP((BC3&BX3&"Template desconto FLAT Plano Principal Oi TV nível conta"),BENEFICIOS!$A:$G,5,0))) | CA3: =IF(BZ3=0,"",IF(BZ3=VLOOKUP("PCS-OzTL744",ARBOR!$A:$C,3,0),0.0001,IF(BZ3>VLOOKUP("PCS-OzTL744",ARBOR!$A:$C,3,0),"Maior que CAP!",IF((DOLLAR(BZ3+(VLOOKUP("PCS-OzTL744",ARBOR!$A:$C,3,0)*-TRUNC(BZ3/VLOOKUP("PCS-OzTL744",ARBOR!$A:$C,3,0)-1,4)),6))<>(DOLLAR(VLOOKUP("PCS-OzTL744",ARBOR!$A:$C,3,0),6)),-TRUNC(BZ3/VLOOKUP("PCS-OzTL744",ARBOR!$A:$C,3,0)-1,4)+0.0001,-TRUNC(BZ3/VLOOKUP("PCS-OzTL744",ARBOR!$A:$C,3,0)-1,4))))) | CB3: =IF(ISERROR(IF(CA3="","",VLOOKUP(($BC3&CA3&"Template desconto FLAT Plano Principal Oi TV nível conta"),BENEFICIOS!$A:$G,5,0))),"Criar",IF(CA3="","",VLOOKUP(($BC3&CA3&"Template desconto FLAT Plano Principal Oi TV nível conta"),BENEFICIOS!$A:$G,5,0))) | CD3: =IF(CC3=0,"",IF(CC3=VLOOKUP("PCS-OzTL743",ARBOR!$A:$C,3,0),0.0001,IF(CC3>VLOOKUP("PCS-OzTL743",ARBOR!$A:$C,3,0),"Maior que CAP!",IF((DOLLAR(CC3+(VLOOKUP("PCS-OzTL743",ARBOR!$A:$C,3,0)*-TRUNC(CC3/VLOOKUP("PCS-OzTL743",ARBOR!$A:$C,3,0)-1,4)),6))<>(DOLLAR(VLOOKUP("PCS-OzTL743",ARBOR!$A:$C,3,0),6)),-TRUNC(CC3/VLOOKUP("PCS-OzTL743",ARBOR!$A:$C,3,0)-1,4)+0.0001,-TRUNC(CC3/VLOOKUP("PCS-OzTL743",ARBOR!$A:$C,3,0)-1,4))))) | CE3: =IF(ISERROR(IF(CD3="","",VLOOKUP(($BC3&CD3&"Template desconto FLAT Plano Principal Oi TV nível conta"),BENEFICIOS!$A:$G,5,0))),"Criar",IF(CD3="","",VLOOKUP(($BC3&CD3&"Template desconto FLAT Plano Principal Oi TV nível conta"),BENEFICIOS!$A:$G,5,0))) | CG3: =IF(CF3=0,"",IF(CF3=VLOOKUP("PCS-OzTL745",ARBOR!$A:$C,3,0),0.0001,IF(CF3>VLOOKUP("PCS-OzTL745",ARBOR!$A:$C,3,0),"Maior que CAP!",IF((DOLLAR(CF3+(VLOOKUP("PCS-OzTL745",ARBOR!$A:$C,3,0)*-TRUNC(CF3/VLOOKUP("PCS-OzTL745",ARBOR!$A:$C,3,0)-1,4)),6))<>(DOLLAR(VLOOKUP("PCS-OzTL745",ARBOR!$A:$C,3,0),6)),-TRUNC(CF3/VLOOKUP("PCS-OzTL745",ARBOR!$A:$C,3,0)-1,4)+0.0001,-TRUNC(CF3/VLOOKUP("PCS-OzTL745",ARBOR!$A:$C,3,0)-1,4))))) | CH3: =IF(ISERROR(IF(CG3="","",VLOOKUP(($BC3&CG3&"Template desconto FLAT Plano Principal Oi TV nível conta"),BENEFICIOS!$A:$G,5,0))),"Criar",IF(CG3="","",VLOOKUP(($BC3&CG3&"Template desconto FLAT Plano Principal Oi TV nível conta"),BENEFICIOS!$A:$G,5,0))) | CJ3: =IF(CI3=0,"",IF(CI3=VLOOKUP("PCS-OzTL42",ARBOR!$A:$C,3,0),0.0001,IF(CI3>VLOOKUP("PCS-OzTL42",ARBOR!$A:$C,3,0),"Maior que CAP!",IF((DOLLAR(CI3+(VLOOKUP("PCS-OzTL42",ARBOR!$A:$C,3,0)*-TRUNC(CI3/VLOOKUP("PCS-OzTL42",ARBOR!$A:$C,3,0)-1,4)),6))<>(DOLLAR(VLOOKUP("PCS-OzTL42",ARBOR!$A:$C,3,0),6)),-TRUNC(CI3/VLOOKUP("PCS-OzTL42",ARBOR!$A:$C,3,0)-1,4)+0.0001,-TRUNC(CI3/VLOOKUP("PCS-OzTL42",ARBOR!$A:$C,3,0)-1,4))))) | CK3: =IF(ISERROR(IF(CJ3="","",VLOOKUP(($BC3&CJ3&"Template desconto FLAT Plano Principal Oi TV nível conta"),BENEFICIOS!$A:$G,5,0))),"Criar",IF(CJ3="","",VLOOKUP(($BC3&CJ3&"Template desconto FLAT Plano Principal Oi TV nível conta"),BENEFICIOS!$A:$G,5,0))) | CM3: =IF(CL3=0,"",IF(CL3=VLOOKUP("PCS-OzTL47",ARBOR!$A:$C,3,0),0.0001,IF(CL3>VLOOKUP("PCS-OzTL47",ARBOR!$A:$C,3,0),"Maior que CAP!",IF((DOLLAR(CL3+(VLOOKUP("PCS-OzTL47",ARBOR!$A:$C,3,0)*-TRUNC(CL3/VLOOKUP("PCS-OzTL47",ARBOR!$A:$C,3,0)-1,4)),6))<>(DOLLAR(VLOOKUP("PCS-OzTL47",ARBOR!$A:$C,3,0),6)),-TRUNC(CL3/VLOOKUP("PCS-OzTL47",ARBOR!$A:$C,3,0)-1,4)+0.0001,-TRUNC(CL3/VLOOKUP("PCS-OzTL47",ARBOR!$A:$C,3,0)-1,4))))) | CN3: =IF(ISERROR(IF(CM3="","",VLOOKUP(($BC3&CM3&"Template desconto FLAT Plano Principal Oi TV nível conta"),BENEFICIOS!$A:$G,5,0))),"Criar",IF(CM3="","",VLOOKUP(($BC3&CM3&"Template desconto FLAT Plano Principal Oi TV nível conta"),BENEFICIOS!$A:$G,5,0))) | CP3: =IF(CO3=0,"",IF(CO3=VLOOKUP("PCS-OzTL46",ARBOR!$A:$C,3,0),0.0001,IF(CO3>VLOOKUP("PCS-OzTL46",ARBOR!$A:$C,3,0),"Maior que CAP!",IF((DOLLAR(CO3+(VLOOKUP("PCS-OzTL46",ARBOR!$A:$C,3,0)*-TRUNC(CO3/VLOOKUP("PCS-OzTL46",ARBOR!$A:$C,3,0)-1,4)),6))<>(DOLLAR(VLOOKUP("PCS-OzTL46",ARBOR!$A:$C,3,0),6)),-TRUNC(CO3/VLOOKUP("PCS-OzTL46",ARBOR!$A:$C,3,0)-1,4)+0.0001,-TRUNC(CO3/VLOOKUP("PCS-OzTL46",ARBOR!$A:$C,3,0)-1,4))))) | CQ3: =IF(ISERROR(IF(CP3="","",VLOOKUP(($BC3&CP3&"Template desconto FLAT Plano Principal Oi TV nível conta"),BENEFICIOS!$A:$G,5,0))),"Criar",IF(CP3="","",VLOOKUP(($BC3&CP3&"Template desconto FLAT Plano Principal Oi TV nível conta"),BENEFICIOS!$A:$G,5,0))) | CS3: =IF(CR3=0,"",IF(CR3=VLOOKUP("PCS-OzTL48",ARBOR!$A:$C,3,0),0.0001,IF(CR3>VLOOKUP("PCS-OzTL48",ARBOR!$A:$C,3,0),"Maior que CAP!",IF((DOLLAR(CR3+(VLOOKUP("PCS-OzTL48",ARBOR!$A:$C,3,0)*-TRUNC(CR3/VLOOKUP("PCS-OzTL48",ARBOR!$A:$C,3,0)-1,4)),6))<>(DOLLAR(VLOOKUP("PCS-OzTL48",ARBOR!$A:$C,3,0),6)),-TRUNC(CR3/VLOOKUP("PCS-OzTL48",ARBOR!$A:$C,3,0)-1,4)+0.0001,-TRUNC(CR3/VLOOKUP("PCS-OzTL48",ARBOR!$A:$C,3,0)-1,4))))) | CT3: =IF(ISERROR(IF(CS3="","",VLOOKUP(($BC3&CS3&"Template desconto FLAT Plano Principal Oi TV nível conta"),BENEFICIOS!$A:$G,5,0))),"Criar",IF(CS3="","",VLOOKUP(($BC3&CS3&"Template desconto FLAT Plano Principal Oi TV nível conta"),BENEFICIOS!$A:$G,5,0))) | CV3: =IF(CU3=0,"",IF(CU3=VLOOKUP("PCS-OzTL742",ARBOR!$A:$C,3,0),0.0001,IF(CU3>VLOOKUP("PCS-OzTL742",ARBOR!$A:$C,3,0),"Maior que CAP!",IF((DOLLAR(CU3+(VLOOKUP("PCS-OzTL742",ARBOR!$A:$C,3,0)*-TRUNC(CU3/VLOOKUP("PCS-OzTL742",ARBOR!$A:$C,3,0)-1,4)),6))<>(DOLLAR(VLOOKUP("PCS-OzTL742",ARBOR!$A:$C,3,0),6)),-TRUNC(CU3/VLOOKUP("PCS-OzTL742",ARBOR!$A:$C,3,0)-1,4)+0.0001,-TRUNC(CU3/VLOOKUP("PCS-OzTL742",ARBOR!$A:$C,3,0)-1,4))))) | CW3: =IF(ISERROR(IF(CV3="","",VLOOKUP(($BC3&CV3&"Template desconto FLAT Plano Principal Oi TV nível conta"),BENEFICIOS!$A:$G,5,0))),"Criar",IF(CV3="","",VLOOKUP(($BC3&CV3&"Template desconto FLAT Plano Principal Oi TV nível conta"),BENEFICIOS!$A:$G,5,0))) | CY3: =IF(CX3=0,"",IF(CX3=VLOOKUP("PCS-OzTL747",ARBOR!$A:$C,3,0),0.0001,IF(CX3>VLOOKUP("PCS-OzTL747",ARBOR!$A:$C,3,0),"Maior que CAP!",IF((DOLLAR(CX3+(VLOOKUP("PCS-OzTL747",ARBOR!$A:$C,3,0)*-TRUNC(CX3/VLOOKUP("PCS-OzTL747",ARBOR!$A:$C,3,0)-1,4)),6))<>(DOLLAR(VLOOKUP("PCS-OzTL747",ARBOR!$A:$C,3,0),6)),-TRUNC(CX3/VLOOKUP("PCS-OzTL747",ARBOR!$A:$C,3,0)-1,4)+0.0001,-TRUNC(CX3/VLOOKUP("PCS-OzTL747",ARBOR!$A:$C,3,0)-1,4))))) | CZ3: =IF(ISERROR(IF(CY3="","",VLOOKUP(($BC3&CY3&"Template desconto FLAT Plano Principal Oi TV nível conta"),BENEFICIOS!$A:$G,5,0))),"Criar",IF(CY3="","",VLOOKUP(($BC3&CY3&"Template desconto FLAT Plano Principal Oi TV nível conta"),BENEFICIOS!$A:$G,5,0))) | DB3: =IF(DA3=0,"",IF(DA3=VLOOKUP("PCS-OzTL746",ARBOR!$A:$C,3,0),0.0001,IF(DA3>VLOOKUP("PCS-OzTL746",ARBOR!$A:$C,3,0),"Maior que CAP!",IF((DOLLAR(DA3+(VLOOKUP("PCS-OzTL746",ARBOR!$A:$C,3,0)*-TRUNC(DA3/VLOOKUP("PCS-OzTL746",ARBOR!$A:$C,3,0)-1,4)),6))<>(DOLLAR(VLOOKUP("PCS-OzTL746",ARBOR!$A:$C,3,0),6)),-TRUNC(DA3/VLOOKUP("PCS-OzTL746",ARBOR!$A:$C,3,0)-1,4)+0.0001,-TRUNC(DA3/VLOOKUP("PCS-OzTL746",ARBOR!$A:$C,3,0)-1,4))))) | DC3: =IF(ISERROR(IF(DB3="","",VLOOKUP(($BC3&DB3&"Template desconto FLAT Plano Principal Oi TV nível conta"),BENEFICIOS!$A:$G,5,0))),"Criar",IF(DB3="","",VLOOKUP(($BC3&DB3&"Template desconto FLAT Plano Principal Oi TV nível conta"),BENEFICIOS!$A:$G,5,0))) | DE3: =IF(DD3=0,"",IF(DD3=VLOOKUP("PCS-OzTL748",ARBOR!$A:$C,3,0),0.0001,IF(DD3>VLOOKUP("PCS-OzTL748",ARBOR!$A:$C,3,0),"Maior que CAP!",IF((DOLLAR(DD3+(VLOOKUP("PCS-OzTL748",ARBOR!$A:$C,3,0)*-TRUNC(DD3/VLOOKUP("PCS-OzTL748",ARBOR!$A:$C,3,0)-1,4)),6))<>(DOLLAR(VLOOKUP("PCS-OzTL748",ARBOR!$A:$C,3,0),6)),-TRUNC(DD3/VLOOKUP("PCS-OzTL748",ARBOR!$A:$C,3,0)-1,4)+0.0001,-TRUNC(DD3/VLOOKUP("PCS-OzTL748",ARBOR!$A:$C,3,0)-1,4))))) | DF3: =IF(ISERROR(IF(DE3="","",VLOOKUP(($BC3&DE3&"Template desconto FLAT Plano Principal Oi TV nível conta"),BENEFICIOS!$A:$G,5,0))),"Criar",IF(DE3="","",VLOOKUP(($BC3&DE3&"Template desconto FLAT Plano Principal Oi TV nível conta"),BENEFICIOS!$A:$G,5,0))) | DG3: 75 | DH3: =IF(DG3=0,"",IF(DG3=VLOOKUP("PCS-OzTL34",ARBOR!$A:$C,3,0),0.0001,IF(DG3>VLOOKUP("PCS-OzTL34",ARBOR!$A:$C,3,0),"Maior que CAP!",IF((DOLLAR(DG3+(VLOOKUP("PCS-OzTL34",ARBOR!$A:$C,3,0)*-TRUNC(DG3/VLOOKUP("PCS-OzTL34",ARBOR!$A:$C,3,0)-1,4)),6))<>(DOLLAR(VLOOKUP("PCS-OzTL34",ARBOR!$A:$C,3,0),6)),-TRUNC(DG3/VLOOKUP("PCS-OzTL34",ARBOR!$A:$C,3,0)-1,4)+0.0001,-TRUNC(DG3/VLOOKUP("PCS-OzTL34",ARBOR!$A:$C,3,0)-1,4))))) -> 0.319 | DI3: =IF(DH3="S/Desc","S/Desc",IF(ISERROR(IF(DH3="","",VLOOKUP(($BC3&DH3&"Template desconto % Combate nível conta"),BENEFICIOS!$A:$G,5,0))),"Criar",IF(DH3="","",VLOOKUP(($BC3&DH3&"Template desconto % Combate nível conta"),BENEFICIOS!$A:$G,5,0)))) -> Criar | DJ3: 19.9 | DK3: =IF(DJ3=0,"",IF(DJ3=VLOOKUP("PCS-OzTL31",ARBOR!$A:$C,3,0),0.0001,IF(DJ3>VLOOKUP("PCS-OzTL31",ARBOR!$A:$C,3,0),"Maior que CAP!",IF((DOLLAR(DJ3+(VLOOKUP("PCS-OzTL31",ARBOR!$A:$C,3,0)*-TRUNC(DJ3/VLOOKUP("PCS-OzTL31",ARBOR!$A:$C,3,0)-1,4)),6))<>(DOLLAR(VLOOKUP("PCS-OzTL31",ARBOR!$A:$C,3,0),6)),-TRUNC(DJ3/VLOOKUP("PCS-OzTL31",ARBOR!$A:$C,3,0)-1,4)+0.0001,-TRUNC(DJ3/VLOOKUP("PCS-OzTL31",ARBOR!$A:$C,3,0)-1,4))))) -> 0.0918 | DL3: =IF(DK3="S/Desc","S/Desc",IF(ISERROR(IF(DK3="","",VLOOKUP(($BC3&DK3&"Template desconto % Sexy Hot nível conta"),BENEFICIOS!$A:$G,5,0))),"Criar",IF(DK3="","",VLOOKUP(($BC3&DK3&"Template desconto % Sexy Hot nível conta"),BENEFICIOS!$A:$G,5,0)))) -> Criar | DM3: 19.9 | DN3: =IF(DM3=0,"",IF(DM3=VLOOKUP("PCS-OzTL32",ARBOR!$A:$C,3,0),0.0001,IF(DM3>VLOOKUP("PCS-OzTL32",ARBOR!$A:$C,3,0),"Maior que CAP!",IF((DOLLAR(DM3+(VLOOKUP("PCS-OzTL32",ARBOR!$A:$C,3,0)*-TRUNC(DM3/VLOOKUP("PCS-OzTL32",ARBOR!$A:$C,3,0)-1,4)),6))<>(DOLLAR(VLOOKUP("PCS-OzTL32",ARBOR!$A:$C,3,0),6)),-TRUNC(DM3/VLOOKUP("PCS-OzTL32",ARBOR!$A:$C,3,0)-1,4)+0.0001,-TRUNC(DM3/VLOOKUP("PCS-OzTL32",ARBOR!$A:$C,3,0)-1,4))))) -> 0.0918 | DO3: =IF(DN3="S/Desc","S/Desc",IF(ISERROR(IF(DN3="","",VLOOKUP(($BC3&DN3&"Template desconto % Playboy nível conta"),BENEFICIOS!$A:$G,5,0))),"Criar",IF(DN3="","",VLOOKUP(($BC3&DN3&"Template desconto % Playboy nível conta"),BENEFICIOS!$A:$G,5,0)))) -> Criar | DP3: 29.9 | DQ3: =IF(DP3=0,"",IF(DP3=VLOOKUP("PCS-OzTL33",ARBOR!$A:$C,3,0),0.0001,IF(DP3>VLOOKUP("PCS-OzTL33",ARBOR!$A:$C,3,0),"Maior que CAP!",IF((DOLLAR(DP3+(VLOOKUP("PCS-OzTL33",ARBOR!$A:$C,3,0)*-TRUNC(DP3/VLOOKUP("PCS-OzTL33",ARBOR!$A:$C,3,0)-1,4)),6))<>(DOLLAR(VLOOKUP("PCS-OzTL33",ARBOR!$A:$C,3,0),6)),-TRUNC(DP3/VLOOKUP("PCS-OzTL33",ARBOR!$A:$C,3,0)-1,4)+0.0001,-TRUNC(DP3/VLOOKUP("PCS-OzTL33",ARBOR!$A:$C,3,0)-1,4))))) -> 0.0918 | DR3: =IF(DQ3="S/Desc","S/Desc",IF(ISERROR(IF(DQ3="","",VLOOKUP(($BC3&DQ3&"Template desconto % Sexy Hot + Playboy nível conta"),BENEFICIOS!$A:$G,5,0))),"Criar",IF(DQ3="","",VLOOKUP(($BC3&DQ3&"Template desconto % Sexy Hot + Playboy nível conta"),BENEFICIOS!$A:$G,5,0)))) -> Criar | DS3: 14.9 | DT3: =IF(DS3=0,"",IF(DS3=VLOOKUP("PCS-OzTL503",ARBOR!$A:$C,3,0),0.0001,IF(DS3>VLOOKUP("PCS-OzTL503",ARBOR!$A:$C,3,0),"Maior que CAP!",IF((DOLLAR(DS3+(VLOOKUP("PCS-OzTL503",ARBOR!$A:$C,3,0)*-TRUNC(DS3/VLOOKUP("PCS-OzTL503",ARBOR!$A:$C,3,0)-1,4)),6))<>(DOLLAR(VLOOKUP("PCS-OzTL503",ARBOR!$A:$C,3,0),6)),-TRUNC(DS3/VLOOKUP("PCS-OzTL503",ARBOR!$A:$C,3,0)-1,4)+0.0001,-TRUNC(DS3/VLOOKUP("PCS-OzTL503",ARBOR!$A:$C,3,0)-1,4))))) -> 0.0915 | DU3: =IF(DT3="S/Desc","S/Desc",IF(ISERROR(IF(DT3="","",VLOOKUP(($BC3&DT3&"Template desconto % SexPrivê nível conta"),BENEFICIOS!$A:$G,5,0))),"Criar",IF(DT3="","",VLOOKUP(($BC3&DT3&"Template desconto % SexPrivê nível conta"),BENEFICIOS!$A:$G,5,0)))) -> Criar | DV3: 10 | DW3: =IF(DV3=0,"",IF(DV3=VLOOKUP("PCS-OzTL500",ARBOR!$A:$C,3,0),0.0001,IF(DV3>VLOOKUP("PCS-OzTL500",ARBOR!$A:$C,3,0),"Maior que CAP!",IF((DOLLAR(DV3+(VLOOKUP("PCS-OzTL500",ARBOR!$A:$C,3,0)*-TRUNC(DV3/VLOOKUP("PCS-OzTL500",ARBOR!$A:$C,3,0)-1,4)),6))<>(DOLLAR(VLOOKUP("PCS-OzTL500",ARBOR!$A:$C,3,0),6)),-TRUNC(DV3/VLOOKUP("PCS-OzTL500",ARBOR!$A:$C,3,0)-1,4)+0.0001,-TRUNC(DV3/VLOOKUP("PCS-OzTL500",ARBOR!$A:$C,3,0)-1,4))))) -> 0.0918 | DX3: =IF(DW3="S/Desc","S/Desc",IF(ISERROR(IF(DW3="","",VLOOKUP(($BC3&DW3&"Template desconto % Étnico nível conta"),BENEFICIOS!$A:$G,5,0))),"Criar",IF(DW3="","",VLOOKUP(($BC3&DW3&"Template desconto % Étnico nível conta"),BENEFICIOS!$A:$G,5,0)))) -> Criar | DZ3: =IF(DY3=0,"",IF(DY3=VLOOKUP("PCS-OzTL50",ARBOR!$A:$C,3,0),0.0001,IF(DY3>VLOOKUP("PCS-OzTL50",ARBOR!$A:$C,3,0),"Maior que CAP!",IF((DOLLAR(DY3+(VLOOKUP("PCS-OzTL50",ARBOR!$A:$C,3,0)*-TRUNC(DY3/VLOOKUP("PCS-OzTL50",ARBOR!$A:$C,3,0)-1,4)),6))<>(DOLLAR(VLOOKUP("PCS-OzTL50",ARBOR!$A:$C,3,0),6)),-TRUNC(DY3/VLOOKUP("PCS-OzTL50",ARBOR!$A:$C,3,0)-1,4)+0.0001,-TRUNC(DY3/VLOOKUP("PCS-OzTL50",ARBOR!$A:$C,3,0)-1,4))))) | EC3: =IF(EB3=0,"",IF(EB3=VLOOKUP("PCS-OzTL51",ARBOR!$A:$C,3,0),0.0001,IF(EB3>VLOOKUP("PCS-OzTL51",ARBOR!$A:$C,3,0),"Maior que CAP!",IF((DOLLAR(EB3+(VLOOKUP("PCS-OzTL51",ARBOR!$A:$C,3,0)*-TRUNC(EB3/VLOOKUP("PCS-OzTL51",ARBOR!$A:$C,3,0)-1,4)),6))<>(DOLLAR(VLOOKUP("PCS-OzTL51",ARBOR!$A:$C,3,0),6)),-TRUNC(EB3/VLOOKUP("PCS-OzTL51",ARBOR!$A:$C,3,0)-1,4)+0.0001,-TRUNC(EB3/VLOOKUP("PCS-OzTL51",ARBOR!$A:$C,3,0)-1,4))))) | EF3: =IF(EE3=0,"",IF(EE3=VLOOKUP("PCS-OzTL52",ARBOR!$A:$C,3,0),0.0001,IF(EE3>VLOOKUP("PCS-OzTL52",ARBOR!$A:$C,3,0),"Maior que CAP!",IF((DOLLAR(EE3+(VLOOKUP("PCS-OzTL52",ARBOR!$A:$C,3,0)*-TRUNC(EE3/VLOOKUP("PCS-OzTL52",ARBOR!$A:$C,3,0)-1,4)),6))<>(DOLLAR(VLOOKUP("PCS-OzTL52",ARBOR!$A:$C,3,0),6)),-TRUNC(EE3/VLOOKUP("PCS-OzTL52",ARBOR!$A:$C,3,0)-1,4)+0.0001,-TRUNC(EE3/VLOOKUP("PCS-OzTL52",ARBOR!$A:$C,3,0)-1,4))))) | EI3: =IF(EH3=0,"",IF(EH3=VLOOKUP("PCS-OzTL53",ARBOR!$A:$C,3,0),0.0001,IF(EH3>VLOOKUP("PCS-OzTL53",ARBOR!$A:$C,3,0),"Maior que CAP!",IF((DOLLAR(EH3+(VLOOKUP("PCS-OzTL53",ARBOR!$A:$C,3,0)*-TRUNC(EH3/VLOOKUP("PCS-OzTL53",ARBOR!$A:$C,3,0)-1,4)),6))<>(DOLLAR(VLOOKUP("PCS-OzTL53",ARBOR!$A:$C,3,0),6)),-TRUNC(EH3/VLOOKUP("PCS-OzTL53",ARBOR!$A:$C,3,0)-1,4)+0.0001,-TRUNC(EH3/VLOOKUP("PCS-OzTL53",ARBOR!$A:$C,3,0)-1,4))))) | EL3: =IF(EK3=0,"",IF(EK3=VLOOKUP("PCS-OzTL54",ARBOR!$A:$C,3,0),0.0001,IF(EK3>VLOOKUP("PCS-OzTL54",ARBOR!$A:$C,3,0),"Maior que CAP!",IF((DOLLAR(EK3+(VLOOKUP("PCS-OzTL54",ARBOR!$A:$C,3,0)*-TRUNC(EK3/VLOOKUP("PCS-OzTL54",ARBOR!$A:$C,3,0)-1,4)),6))<>(DOLLAR(VLOOKUP("PCS-OzTL54",ARBOR!$A:$C,3,0),6)),-TRUNC(EK3/VLOOKUP("PCS-OzTL54",ARBOR!$A:$C,3,0)-1,4)+0.0001,-TRUNC(EK3/VLOOKUP("PCS-OzTL54",ARBOR!$A:$C,3,0)-1,4))))) | EN3: 24.9 | EO3: =IF(EN3=0,"",IF(EN3=VLOOKUP("PCS-OzTL99",ARBOR!$A:$C,3,0),0.0001,IF(EN3>VLOOKUP("PCS-OzTL99",ARBOR!$A:$C,3,0),"Maior que CAP!",IF((DOLLAR(EN3+(VLOOKUP("PCS-OzTL99",ARBOR!$A:$C,3,0)*-TRUNC(EN3/VLOOKUP("PCS-OzTL99",ARBOR!$A:$C,3,0)-1,4)),6))<>(DOLLAR(VLOOKUP("PCS-OzTL99",ARBOR!$A:$C,3,0),6)),-TRUNC(EN3/VLOOKUP("PCS-OzTL99",ARBOR!$A:$C,3,0)-1,4)+0.0001,-TRUNC(EN3/VLOOKUP("PCS-OzTL99",ARBOR!$A:$C,3,0)-1,4))))) -> 0.1673 | EP3: =IF(EO3="S/Desc","S/Desc",IF(ISERROR(IF(EO3="","",VLOOKUP(($BC3&EO3&"Template desconto % Ponto adicional nível conta"),BENEFICIOS!$A:$G,5,0))),"Criar",IF(EO3="","",VLOOKUP(($BC3&EO3&"Template desconto % Ponto adicional nível conta"),BENEFICIOS!$A:$G,5,0)))) -> Criar | ER3: =IF(EQ3="Sim","PCS-34704","") | ES3: Sim | ET3: Benefício | EU3: 499 | EV3: 12 | EW3: =IF(ET3="Benefício","Oi benefício fidelização Multiprodutos","") -> Oi benefício fidelização Multiprodutos | EX3: =IF(ET3="Benefício","PCS-Fk83324","") -> PCS-Fk83324 | EY3: =IF(ES3="Sim","PCS-SBL553142","") -> PCS-SBL553142 | EZ3: LD + VC Oi | FA3: 0T0T_FTV_MIN_LD_270000. | FG3: =IF($BH3="","",$BH3+$BE3) -> 134.9 | FH3: =IF($BK3="","",$BK3+$BE3) | FI3: =IF($BN3="","",$BN3+$BE3) | FJ3: =IF($BQ3="","",$BQ3+$BE3) | FK3: =IF($BT3="","",$BT3+$BE3) | FL3: =IF($BW3="","",$BW3+$BE3) | FM3: =IF($BZ3="","",$BZ3+$BE3) | FN3: =IF($CC3="","",$CC3+$BE3) | FO3: =IF($CF3="","",$CF3+$BE3) | FP3: =IF($CI3="","",$CI3+$BE3) | FQ3: =IF($CL3="","",$CL3+$BE3) | FR3: =IF($CO3="","",$CO3+$BE3) | FS3: =IF($CR3="","",$CR3+$BE3) | FT3: =IF($CU3="","",$CU3+$BE3) | FU3: =IF($CX3="","",$CX3+$BE3) | FV3: =IF($DA3="","",$DA3+$BE3) | FW3: =IF($DD3="","",$DD3+$BE3)
A4: Oi Total | B4: Migração | C4: Atuais | D4: Não | AM4: OT_ATV_JUL17_FID_DACC_2PTV_TV2_MI-TO_LD-VC_OF1 | AN4: Rentabilizar atuais clientes do plano | AO4: Produto Fixo + TV , Produto com fidelização | AP4: 42917 | AQ4: 43039 | AR4: 20. Oi Total | AS4: 20. Oi Total | AU4: Varejo | AV4: 20 | AW4: 10000 | AX4: Campanha Restrita | AY4: Sim | AZ4: Sim | BA4: Não | BB4: OT_ATV_JUL17_FID_DACC_2PTV_TV2_MI-TO_LD-VC_OF1 | BC4: Oi Total Fixo + TV 2 | BD4: =IF(BC4="Oi Total Fixo + TV 1","CFG-2Plowpi",IF(BC4="Oi Total Fixo + TV 2","PCS-2PMepi",IF(BC4="Oi Total Fixo + TV 3","PCS-2PHipi",""))) -> PCS-2PMepi | BE4: 60 | BF4: =IF(BE4=0,"",IF(BE4=VLOOKUP("FIXO",ARBOR!$A:$C,3,0),0.0001,IF(BE4>VLOOKUP("FIXO",ARBOR!$A:$C,3,0),"Maior que CAP!",IF((DOLLAR(BE4+(VLOOKUP("FIXO",ARBOR!$A:$C,3,0)*-TRUNC(BE4/VLOOKUP("FIXO",ARBOR!$A:$C,3,0)-1,4)),6))<>(DOLLAR(VLOOKUP("FIXO",ARBOR!$A:$C,3,0),6)),-TRUNC(BE4/VLOOKUP("FIXO",ARBOR!$A:$C,3,0)-1,4)+0.0001,-TRUNC(BE4/VLOOKUP("FIXO",ARBOR!$A:$C,3,0)-1,4))))) -> 0.2089 | BG4: =IF(ISERROR(IF(BF4="","",VLOOKUP(($BC4&BF4&"Template de desconto FLAT bundle - Fixo - Varejo - Ganho Tributário Cross"),BENEFICIOS!$A:$G,5,0))),"Criar",IF(BF4="","",VLOOKUP(($BC4&BF4&"Template de desconto FLAT bundle - Fixo - Varejo - Ganho Tributário Cross"),BENEFICIOS!$A:$G,5,0))) -> Criar | BI4: =IF(BH4=0,"",IF(BH4=VLOOKUP("PCS-OzTL40",ARBOR!$A:$C,3,0),0.0001,IF(BH4>VLOOKUP("PCS-OzTL40",ARBOR!$A:$C,3,0),"Maior que CAP!",IF((DOLLAR(BH4+(VLOOKUP("PCS-OzTL40",ARBOR!$A:$C,3,0)*-TRUNC(BH4/VLOOKUP("PCS-OzTL40",ARBOR!$A:$C,3,0)-1,4)),6))<>(DOLLAR(VLOOKUP("PCS-OzTL40",ARBOR!$A:$C,3,0),6)),-TRUNC(BH4/VLOOKUP("PCS-OzTL40",ARBOR!$A:$C,3,0)-1,4)+0.0001,-TRUNC(BH4/VLOOKUP("PCS-OzTL40",ARBOR!$A:$C,3,0)-1,4))))) | BJ4: =IF(ISERROR(IF(BI4="","",VLOOKUP((BC4&BI4&"Template desconto FLAT Plano Principal Oi TV nível conta"),BENEFICIOS!$A:$G,5,0))),"Criar",IF(BI4="","",VLOOKUP((BC4&BI4&"Template desconto FLAT Plano Principal Oi TV nível conta"),BENEFICIOS!$A:$G,5,0))) | BK4: 94.9 | BL4: =IF(BK4=0,"",IF(BK4=VLOOKUP("PCS-OzTL41",ARBOR!$A:$C,3,0),0.0001,IF(BK4>VLOOKUP("PCS-OzTL41",ARBOR!$A:$C,3,0),"Maior que CAP!",IF((DOLLAR(BK4+(VLOOKUP("PCS-OzTL41",ARBOR!$A:$C,3,0)*-TRUNC(BK4/VLOOKUP("PCS-OzTL41",ARBOR!$A:$C,3,0)-1,4)),6))<>(DOLLAR(VLOOKUP("PCS-OzTL41",ARBOR!$A:$C,3,0),6)),-TRUNC(BK4/VLOOKUP("PCS-OzTL41",ARBOR!$A:$C,3,0)-1,4)+0.0001,-TRUNC(BK4/VLOOKUP("PCS-OzTL41",ARBOR!$A:$C,3,0)-1,4))))) -> 0.2159 | BM4: =IF(ISERROR(IF(BL4="","",VLOOKUP((BC4&BL4&"Template desconto FLAT Plano Principal Oi TV nível conta"),BENEFICIOS!$A:$G,5,0))),"Criar",IF(BL4="","",VLOOKUP((BC4&BL4&"Template desconto FLAT Plano Principal Oi TV nível conta"),BENEFICIOS!$A:$G,5,0))) -> Criar | BO4: =IF(BN4=0,"",IF(BN4=VLOOKUP("PCS-OzTL44",ARBOR!$A:$C,3,0),0.0001,IF(BN4>VLOOKUP("PCS-OzTL44",ARBOR!$A:$C,3,0),"Maior que CAP!",IF((DOLLAR(BN4+(VLOOKUP("PCS-OzTL44",ARBOR!$A:$C,3,0)*-TRUNC(BN4/VLOOKUP("PCS-OzTL44",ARBOR!$A:$C,3,0)-1,4)),6))<>(DOLLAR(VLOOKUP("PCS-OzTL44",ARBOR!$A:$C,3,0),6)),-TRUNC(BN4/VLOOKUP("PCS-OzTL44",ARBOR!$A:$C,3,0)-1,4)+0.0001,-TRUNC(BN4/VLOOKUP("PCS-OzTL44",ARBOR!$A:$C,3,0)-1,4))))) | BP4: =IF(ISERROR(IF(BO4="","",VLOOKUP((BC4&BO4&"Template desconto FLAT Plano Principal Oi TV nível conta"),BENEFICIOS!$A:$G,5,0))),"Criar",IF(BO4="","",VLOOKUP((BC4&BO4&"Template desconto FLAT Plano Principal Oi TV nível conta"),BENEFICIOS!$A:$G,5,0))) | BR4: =IF(BQ4=0,"",IF(BQ4=VLOOKUP("PCS-OzTL43",ARBOR!$A:$C,3,0),0.0001,IF(BQ4>VLOOKUP("PCS-OzTL43",ARBOR!$A:$C,3,0),"Maior que CAP!",IF((DOLLAR(BQ4+(VLOOKUP("PCS-OzTL43",ARBOR!$A:$C,3,0)*-TRUNC(BQ4/VLOOKUP("PCS-OzTL43",ARBOR!$A:$C,3,0)-1,4)),6))<>(DOLLAR(VLOOKUP("PCS-OzTL43",ARBOR!$A:$C,3,0),6)),-TRUNC(BQ4/VLOOKUP("PCS-OzTL43",ARBOR!$A:$C,3,0)-1,4)+0.0001,-TRUNC(BQ4/VLOOKUP("PCS-OzTL43",ARBOR!$A:$C,3,0)-1,4))))) | BS4: =IF(ISERROR(IF(BR4="","",VLOOKUP((BC4&BR4&"Template desconto FLAT Plano Principal Oi TV nível conta"),BENEFICIOS!$A:$G,5,0))),"Criar",IF(BR4="","",VLOOKUP((BC4&BR4&"Template desconto FLAT Plano Principal Oi TV nível conta"),BENEFICIOS!$A:$G,5,0))) | BU4: =IF(BT4=0,"",IF(BT4=VLOOKUP("PCS-OzTL45",ARBOR!$A:$C,3,0),0.0001,IF(BT4>VLOOKUP("PCS-OzTL45",ARBOR!$A:$C,3,0),"Maior que CAP!",IF((DOLLAR(BT4+(VLOOKUP("PCS-OzTL45",ARBOR!$A:$C,3,0)*-TRUNC(BT4/VLOOKUP("PCS-OzTL45",ARBOR!$A:$C,3,0)-1,4)),6))<>(DOLLAR(VLOOKUP("PCS-OzTL45",ARBOR!$A:$C,3,0),6)),-TRUNC(BT4/VLOOKUP("PCS-OzTL45",ARBOR!$A:$C,3,0)-1,4)+0.0001,-TRUNC(BT4/VLOOKUP("PCS-OzTL45",ARBOR!$A:$C,3,0)-1,4))))) | BV4: =IF(ISERROR(IF(BU4="","",VLOOKUP((BC4&BU4&"Template desconto FLAT Plano Principal Oi TV nível conta"),BENEFICIOS!$A:$G,5,0))),"Criar",IF(BU4="","",VLOOKUP((BC4&BU4&"Template desconto FLAT Plano Principal Oi TV nível conta"),BENEFICIOS!$A:$G,5,0))) | BX4: =IF(BW4=0,"",IF(BW4=VLOOKUP("PCS-OzTL741",ARBOR!$A:$C,3,0),0.0001,IF(BW4>VLOOKUP("PCS-OzTL741",ARBOR!$A:$C,3,0),"Maior que CAP!",IF((DOLLAR(BW4+(VLOOKUP("PCS-OzTL741",ARBOR!$A:$C,3,0)*-TRUNC(BW4/VLOOKUP("PCS-OzTL741",ARBOR!$A:$C,3,0)-1,4)),6))<>(DOLLAR(VLOOKUP("PCS-OzTL741",ARBOR!$A:$C,3,0),6)),-TRUNC(BW4/VLOOKUP("PCS-OzTL741",ARBOR!$A:$C,3,0)-1,4)+0.0001,-TRUNC(BW4/VLOOKUP("PCS-OzTL741",ARBOR!$A:$C,3,0)-1,4))))) | BY4: =IF(ISERROR(IF(BX4="","",VLOOKUP((BC4&BX4&"Template desconto FLAT Plano Principal Oi TV nível conta"),BENEFICIOS!$A:$G,5,0))),"Criar",IF(BX4="","",VLOOKUP((BC4&BX4&"Template desconto FLAT Plano Principal Oi TV nível conta"),BENEFICIOS!$A:$G,5,0))) | CA4: =IF(BZ4=0,"",IF(BZ4=VLOOKUP("PCS-OzTL744",ARBOR!$A:$C,3,0),0.0001,IF(BZ4>VLOOKUP("PCS-OzTL744",ARBOR!$A:$C,3,0),"Maior que CAP!",IF((DOLLAR(BZ4+(VLOOKUP("PCS-OzTL744",ARBOR!$A:$C,3,0)*-TRUNC(BZ4/VLOOKUP("PCS-OzTL744",ARBOR!$A:$C,3,0)-1,4)),6))<>(DOLLAR(VLOOKUP("PCS-OzTL744",ARBOR!$A:$C,3,0),6)),-TRUNC(BZ4/VLOOKUP("PCS-OzTL744",ARBOR!$A:$C,3,0)-1,4)+0.0001,-TRUNC(BZ4/VLOOKUP("PCS-OzTL744",ARBOR!$A:$C,3,0)-1,4))))) | CB4: =IF(ISERROR(IF(CA4="","",VLOOKUP(($BC4&CA4&"Template desconto FLAT Plano Principal Oi TV nível conta"),BENEFICIOS!$A:$G,5,0))),"Criar",IF(CA4="","",VLOOKUP(($BC4&CA4&"Template desconto FLAT Plano Principal Oi TV nível conta"),BENEFICIOS!$A:$G,5,0))) | CD4: =IF(CC4=0,"",IF(CC4=VLOOKUP("PCS-OzTL743",ARBOR!$A:$C,3,0),0.0001,IF(CC4>VLOOKUP("PCS-OzTL743",ARBOR!$A:$C,3,0),"Maior que CAP!",IF((DOLLAR(CC4+(VLOOKUP("PCS-OzTL743",ARBOR!$A:$C,3,0)*-TRUNC(CC4/VLOOKUP("PCS-OzTL743",ARBOR!$A:$C,3,0)-1,4)),6))<>(DOLLAR(VLOOKUP("PCS-OzTL743",ARBOR!$A:$C,3,0),6)),-TRUNC(CC4/VLOOKUP("PCS-OzTL743",ARBOR!$A:$C,3,0)-1,4)+0.0001,-TRUNC(CC4/VLOOKUP("PCS-OzTL743",ARBOR!$A:$C,3,0)-1,4))))) | CE4: =IF(ISERROR(IF(CD4="","",VLOOKUP(($BC4&CD4&"Template desconto FLAT Plano Principal Oi TV nível conta"),BENEFICIOS!$A:$G,5,0))),"Criar",IF(CD4="","",VLOOKUP(($BC4&CD4&"Template desconto FLAT Plano Principal Oi TV nível conta"),BENEFICIOS!$A:$G,5,0))) | CG4: =IF(CF4=0,"",IF(CF4=VLOOKUP("PCS-OzTL745",ARBOR!$A:$C,3,0),0.0001,IF(CF4>VLOOKUP("PCS-OzTL745",ARBOR!$A:$C,3,0),"Maior que CAP!",IF((DOLLAR(CF4+(VLOOKUP("PCS-OzTL745",ARBOR!$A:$C,3,0)*-TRUNC(CF4/VLOOKUP("PCS-OzTL745",ARBOR!$A:$C,3,0)-1,4)),6))<>(DOLLAR(VLOOKUP("PCS-OzTL745",ARBOR!$A:$C,3,0),6)),-TRUNC(CF4/VLOOKUP("PCS-OzTL745",ARBOR!$A:$C,3,0)-1,4)+0.0001,-TRUNC(CF4/VLOOKUP("PCS-OzTL745",ARBOR!$A:$C,3,0)-1,4))))) | CH4: =IF(ISERROR(IF(CG4="","",VLOOKUP(($BC4&CG4&"Template desconto FLAT Plano Principal Oi TV nível conta"),BENEFICIOS!$A:$G,5,0))),"Criar",IF(CG4="","",VLOOKUP(($BC4&CG4&"Template desconto FLAT Plano Principal Oi TV nível conta"),BENEFICIOS!$A:$G,5,0))) | CI4: 104.9 | CJ4: =IF(CI4=0,"",IF(CI4=VLOOKUP("PCS-OzTL42",ARBOR!$A:$C,3,0),0.0001,IF(CI4>VLOOKUP("PCS-OzTL42",ARBOR!$A:$C,3,0),"Maior que CAP!",IF((DOLLAR(CI4+(VLOOKUP("PCS-OzTL42",ARBOR!$A:$C,3,0)*-TRUNC(CI4/VLOOKUP("PCS-OzTL42",ARBOR!$A:$C,3,0)-1,4)),6))<>(DOLLAR(VLOOKUP("PCS-OzTL42",ARBOR!$A:$C,3,0),6)),-TRUNC(CI4/VLOOKUP("PCS-OzTL42",ARBOR!$A:$C,3,0)-1,4)+0.0001,-TRUNC(CI4/VLOOKUP("PCS-OzTL42",ARBOR!$A:$C,3,0)-1,4))))) -> 0.3646 | CK4: =IF(ISERROR(IF(CJ4="","",VLOOKUP(($BC4&CJ4&"Template desconto FLAT Plano Principal Oi TV nível conta"),BENEFICIOS!$A:$G,5,0))),"Criar",IF(CJ4="","",VLOOKUP(($BC4&CJ4&"Template desconto FLAT Plano Principal Oi TV nível conta"),BENEFICIOS!$A:$G,5,0))) -> Criar | CM4: =IF(CL4=0,"",IF(CL4=VLOOKUP("PCS-OzTL47",ARBOR!$A:$C,3,0),0.0001,IF(CL4>VLOOKUP("PCS-OzTL47",ARBOR!$A:$C,3,0),"Maior que CAP!",IF((DOLLAR(CL4+(VLOOKUP("PCS-OzTL47",ARBOR!$A:$C,3,0)*-TRUNC(CL4/VLOOKUP("PCS-OzTL47",ARBOR!$A:$C,3,0)-1,4)),6))<>(DOLLAR(VLOOKUP("PCS-OzTL47",ARBOR!$A:$C,3,0),6)),-TRUNC(CL4/VLOOKUP("PCS-OzTL47",ARBOR!$A:$C,3,0)-1,4)+0.0001,-TRUNC(CL4/VLOOKUP("PCS-OzTL47",ARBOR!$A:$C,3,0)-1,4))))) | CN4: =IF(ISERROR(IF(CM4="","",VLOOKUP(($BC4&CM4&"Template desconto FLAT Plano Principal Oi TV nível conta"),BENEFICIOS!$A:$G,5,0))),"Criar",IF(CM4="","",VLOOKUP(($BC4&CM4&"Template desconto FLAT Plano Principal Oi TV nível conta"),BENEFICIOS!$A:$G,5,0))) | CP4: =IF(CO4=0,"",IF(CO4=VLOOKUP("PCS-OzTL46",ARBOR!$A:$C,3,0),0.0001,IF(CO4>VLOOKUP("PCS-OzTL46",ARBOR!$A:$C,3,0),"Maior que CAP!",IF((DOLLAR(CO4+(VLOOKUP("PCS-OzTL46",ARBOR!$A:$C,3,0)*-TRUNC(CO4/VLOOKUP("PCS-OzTL46",ARBOR!$A:$C,3,0)-1,4)),6))<>(DOLLAR(VLOOKUP("PCS-OzTL46",ARBOR!$A:$C,3,0),6)),-TRUNC(CO4/VLOOKUP("PCS-OzTL46",ARBOR!$A:$C,3,0)-1,4)+0.0001,-TRUNC(CO4/VLOOKUP("PCS-OzTL46",ARBOR!$A:$C,3,0)-1,4))))) | CQ4: =IF(ISERROR(IF(CP4="","",VLOOKUP(($BC4&CP4&"Template desconto FLAT Plano Principal Oi TV nível conta"),BENEFICIOS!$A:$G,5,0))),"Criar",IF(CP4="","",VLOOKUP(($BC4&CP4&"Template desconto FLAT Plano Principal Oi TV nível conta"),BENEFICIOS!$A:$G,5,0))) | CS4: =IF(CR4=0,"",IF(CR4=VLOOKUP("PCS-OzTL48",ARBOR!$A:$C,3,0),0.0001,IF(CR4>VLOOKUP("PCS-OzTL48",ARBOR!$A:$C,3,0),"Maior que CAP!",IF((DOLLAR(CR4+(VLOOKUP("PCS-OzTL48",ARBOR!$A:$C,3,0)*-TRUNC(CR4/VLOOKUP("PCS-OzTL48",ARBOR!$A:$C,3,0)-1,4)),6))<>(DOLLAR(VLOOKUP("PCS-OzTL48",ARBOR!$A:$C,3,0),6)),-TRUNC(CR4/VLOOKUP("PCS-OzTL48",ARBOR!$A:$C,3,0)-1,4)+0.0001,-TRUNC(CR4/VLOOKUP("PCS-OzTL48",ARBOR!$A:$C,3,0)-1,4))))) | CT4: =IF(ISERROR(IF(CS4="","",VLOOKUP(($BC4&CS4&"Template desconto FLAT Plano Principal Oi TV nível conta"),BENEFICIOS!$A:$G,5,0))),"Criar",IF(CS4="","",VLOOKUP(($BC4&CS4&"Template desconto FLAT Plano Principal Oi TV nível conta"),BENEFICIOS!$A:$G,5,0))) | CU4: 124.9 | CV4: =IF(CU4=0,"",IF(CU4=VLOOKUP("PCS-OzTL742",ARBOR!$A:$C,3,0),0.0001,IF(CU4>VLOOKUP("PCS-OzTL742",ARBOR!$A:$C,3,0),"Maior que CAP!",IF((DOLLAR(CU4+(VLOOKUP("PCS-OzTL742",ARBOR!$A:$C,3,0)*-TRUNC(CU4/VLOOKUP("PCS-OzTL742",ARBOR!$A:$C,3,0)-1,4)),6))<>(DOLLAR(VLOOKUP("PCS-OzTL742",ARBOR!$A:$C,3,0),6)),-TRUNC(CU4/VLOOKUP("PCS-OzTL742",ARBOR!$A:$C,3,0)-1,4)+0.0001,-TRUNC(CU4/VLOOKUP("PCS-OzTL742",ARBOR!$A:$C,3,0)-1,4))))) -> 0.4327 | CW4: =IF(ISERROR(IF(CV4="","",VLOOKUP(($BC4&CV4&"Template desconto FLAT Plano Principal Oi TV nível conta"),BENEFICIOS!$A:$G,5,0))),"Criar",IF(CV4="","",VLOOKUP(($BC4&CV4&"Template desconto FLAT Plano Principal Oi TV nível conta"),BENEFICIOS!$A:$G,5,0))) -> Criar | CY4: =IF(CX4=0,"",IF(CX4=VLOOKUP("PCS-OzTL747",ARBOR!$A:$C,3,0),0.0001,IF(CX4>VLOOKUP("PCS-OzTL747",ARBOR!$A:$C,3,0),"Maior que CAP!",IF((DOLLAR(CX4+(VLOOKUP("PCS-OzTL747",ARBOR!$A:$C,3,0)*-TRUNC(CX4/VLOOKUP("PCS-OzTL747",ARBOR!$A:$C,3,0)-1,4)),6))<>(DOLLAR(VLOOKUP("PCS-OzTL747",ARBOR!$A:$C,3,0),6)),-TRUNC(CX4/VLOOKUP("PCS-OzTL747",ARBOR!$A:$C,3,0)-1,4)+0.0001,-TRUNC(CX4/VLOOKUP("PCS-OzTL747",ARBOR!$A:$C,3,0)-1,4))))) | CZ4: =IF(ISERROR(IF(CY4="","",VLOOKUP(($BC4&CY4&"Template desconto FLAT Plano Principal Oi TV nível conta"),BENEFICIOS!$A:$G,5,0))),"Criar",IF(CY4="","",VLOOKUP(($BC4&CY4&"Template desconto FLAT Plano Principal Oi TV nível conta"),BENEFICIOS!$A:$G,5,0))) | DB4: =IF(DA4=0,"",IF(DA4=VLOOKUP("PCS-OzTL746",ARBOR!$A:$C,3,0),0.0001,IF(DA4>VLOOKUP("PCS-OzTL746",ARBOR!$A:$C,3,0),"Maior que CAP!",IF((DOLLAR(DA4+(VLOOKUP("PCS-OzTL746",ARBOR!$A:$C,3,0)*-TRUNC(DA4/VLOOKUP("PCS-OzTL746",ARBOR!$A:$C,3,0)-1,4)),6))<>(DOLLAR(VLOOKUP("PCS-OzTL746",ARBOR!$A:$C,3,0),6)),-TRUNC(DA4/VLOOKUP("PCS-OzTL746",ARBOR!$A:$C,3,0)-1,4)+0.0001,-TRUNC(DA4/VLOOKUP("PCS-OzTL746",ARBOR!$A:$C,3,0)-1,4))))) | DC4: =IF(ISERROR(IF(DB4="","",VLOOKUP(($BC4&DB4&"Template desconto FLAT Plano Principal Oi TV nível conta"),BENEFICIOS!$A:$G,5,0))),"Criar",IF(DB4="","",VLOOKUP(($BC4&DB4&"Template desconto FLAT Plano Principal Oi TV nível conta"),BENEFICIOS!$A:$G,5,0))) | DE4: =IF(DD4=0,"",IF(DD4=VLOOKUP("PCS-OzTL748",ARBOR!$A:$C,3,0),0.0001,IF(DD4>VLOOKUP("PCS-OzTL748",ARBOR!$A:$C,3,0),"Maior que CAP!",IF((DOLLAR(DD4+(VLOOKUP("PCS-OzTL748",ARBOR!$A:$C,3,0)*-TRUNC(DD4/VLOOKUP("PCS-OzTL748",ARBOR!$A:$C,3,0)-1,4)),6))<>(DOLLAR(VLOOKUP("PCS-OzTL748",ARBOR!$A:$C,3,0),6)),-TRUNC(DD4/VLOOKUP("PCS-OzTL748",ARBOR!$A:$C,3,0)-1,4)+0.0001,-TRUNC(DD4/VLOOKUP("PCS-OzTL748",ARBOR!$A:$C,3,0)-1,4))))) | DF4: =IF(ISERROR(IF(DE4="","",VLOOKUP(($BC4&DE4&"Template desconto FLAT Plano Principal Oi TV nível conta"),BENEFICIOS!$A:$G,5,0))),"Criar",IF(DE4="","",VLOOKUP(($BC4&DE4&"Template desconto FLAT Plano Principal Oi TV nível conta"),BENEFICIOS!$A:$G,5,0))) | DG4: 75 | DH4: =IF(DG4=0,"",IF(DG4=VLOOKUP("PCS-OzTL34",ARBOR!$A:$C,3,0),0.0001,IF(DG4>VLOOKUP("PCS-OzTL34",ARBOR!$A:$C,3,0),"Maior que CAP!",IF((DOLLAR(DG4+(VLOOKUP("PCS-OzTL34",ARBOR!$A:$C,3,0)*-TRUNC(DG4/VLOOKUP("PCS-OzTL34",ARBOR!$A:$C,3,0)-1,4)),6))<>(DOLLAR(VLOOKUP("PCS-OzTL34",ARBOR!$A:$C,3,0),6)),-TRUNC(DG4/VLOOKUP("PCS-OzTL34",ARBOR!$A:$C,3,0)-1,4)+0.0001,-TRUNC(DG4/VLOOKUP("PCS-OzTL34",ARBOR!$A:$C,3,0)-1,4))))) -> 0.319 | DI4: =IF(DH4="S/Desc","S/Desc",IF(ISERROR(IF(DH4="","",VLOOKUP(($BC4&DH4&"Template desconto % Combate nível conta"),BENEFICIOS!$A:$G,5,0))),"Criar",IF(DH4="","",VLOOKUP(($BC4&DH4&"Template desconto % Combate nível conta"),BENEFICIOS!$A:$G,5,0)))) -> Criar | DJ4: 19.9 | DK4: =IF(DJ4=0,"",IF(DJ4=VLOOKUP("PCS-OzTL31",ARBOR!$A:$C,3,0),0.0001,IF(DJ4>VLOOKUP("PCS-OzTL31",ARBOR!$A:$C,3,0),"Maior que CAP!",IF((DOLLAR(DJ4+(VLOOKUP("PCS-OzTL31",ARBOR!$A:$C,3,0)*-TRUNC(DJ4/VLOOKUP("PCS-OzTL31",ARBOR!$A:$C,3,0)-1,4)),6))<>(DOLLAR(VLOOKUP("PCS-OzTL31",ARBOR!$A:$C,3,0),6)),-TRUNC(DJ4/VLOOKUP("PCS-OzTL31",ARBOR!$A:$C,3,0)-1,4)+0.0001,-TRUNC(DJ4/VLOOKUP("PCS-OzTL31",ARBOR!$A:$C,3,0)-1,4))))) -> 0.0918 | DL4: =IF(DK4="S/Desc","S/Desc",IF(ISERROR(IF(DK4="","",VLOOKUP(($BC4&DK4&"Template desconto % Sexy Hot nível conta"),BENEFICIOS!$A:$G,5,0))),"Criar",IF(DK4="","",VLOOKUP(($BC4&DK4&"Template desconto % Sexy Hot nível conta"),BENEFICIOS!$A:$G,5,0)))) -> Criar | DM4: 19.9 | DN4: =IF(DM4=0,"",IF(DM4=VLOOKUP("PCS-OzTL32",ARBOR!$A:$C,3,0),0.0001,IF(DM4>VLOOKUP("PCS-OzTL32",ARBOR!$A:$C,3,0),"Maior que CAP!",IF((DOLLAR(DM4+(VLOOKUP("PCS-OzTL32",ARBOR!$A:$C,3,0)*-TRUNC(DM4/VLOOKUP("PCS-OzTL32",ARBOR!$A:$C,3,0)-1,4)),6))<>(DOLLAR(VLOOKUP("PCS-OzTL32",ARBOR!$A:$C,3,0),6)),-TRUNC(DM4/VLOOKUP("PCS-OzTL32",ARBOR!$A:$C,3,0)-1,4)+0.0001,-TRUNC(DM4/VLOOKUP("PCS-OzTL32",ARBOR!$A:$C,3,0)-1,4))))) -> 0.0918 | DO4: =IF(DN4="S/Desc","S/Desc",IF(ISERROR(IF(DN4="","",VLOOKUP(($BC4&DN4&"Template desconto % Playboy nível conta"),BENEFICIOS!$A:$G,5,0))),"Criar",IF(DN4="","",VLOOKUP(($BC4&DN4&"Template desconto % Playboy nível conta"),BENEFICIOS!$A:$G,5,0)))) -> Criar | DP4: 29.9 | DQ4: =IF(DP4=0,"",IF(DP4=VLOOKUP("PCS-OzTL33",ARBOR!$A:$C,3,0),0.0001,IF(DP4>VLOOKUP("PCS-OzTL33",ARBOR!$A:$C,3,0),"Maior que CAP!",IF((DOLLAR(DP4+(VLOOKUP("PCS-OzTL33",ARBOR!$A:$C,3,0)*-TRUNC(DP4/VLOOKUP("PCS-OzTL33",ARBOR!$A:$C,3,0)-1,4)),6))<>(DOLLAR(VLOOKUP("PCS-OzTL33",ARBOR!$A:$C,3,0),6)),-TRUNC(DP4/VLOOKUP("PCS-OzTL33",ARBOR!$A:$C,3,0)-1,4)+0.0001,-TRUNC(DP4/VLOOKUP("PCS-OzTL33",ARBOR!$A:$C,3,0)-1,4))))) -> 0.0918 | DR4: =IF(DQ4="S/Desc","S/Desc",IF(ISERROR(IF(DQ4="","",VLOOKUP(($BC4&DQ4&"Template desconto % Sexy Hot + Playboy nível conta"),BENEFICIOS!$A:$G,5,0))),"Criar",IF(DQ4="","",VLOOKUP(($BC4&DQ4&"Template desconto % Sexy Hot + Playboy nível conta"),BENEFICIOS!$A:$G,5,0)))) -> Criar | DS4: 14.9 | DT4: =IF(DS4=0,"",IF(DS4=VLOOKUP("PCS-OzTL503",ARBOR!$A:$C,3,0),0.0001,IF(DS4>VLOOKUP("PCS-OzTL503",ARBOR!$A:$C,3,0),"Maior que CAP!",IF((DOLLAR(DS4+(VLOOKUP("PCS-OzTL503",ARBOR!$A:$C,3,0)*-TRUNC(DS4/VLOOKUP("PCS-OzTL503",ARBOR!$A:$C,3,0)-1,4)),6))<>(DOLLAR(VLOOKUP("PCS-OzTL503",ARBOR!$A:$C,3,0),6)),-TRUNC(DS4/VLOOKUP("PCS-OzTL503",ARBOR!$A:$C,3,0)-1,4)+0.0001,-TRUNC(DS4/VLOOKUP("PCS-OzTL503",ARBOR!$A:$C,3,0)-1,4))))) -> 0.0915 | DU4: =IF(DT4="S/Desc","S/Desc",IF(ISERROR(IF(DT4="","",VLOOKUP(($BC4&DT4&"Template desconto % SexPrivê nível conta"),BENEFICIOS!$A:$G,5,0))),"Criar",IF(DT4="","",VLOOKUP(($BC4&DT4&"Template desconto % SexPrivê nível conta"),BENEFICIOS!$A:$G,5,0)))) -> Criar | DV4: 10 | DW4: =IF(DV4=0,"",IF(DV4=VLOOKUP("PCS-OzTL500",ARBOR!$A:$C,3,0),0.0001,IF(DV4>VLOOKUP("PCS-OzTL500",ARBOR!$A:$C,3,0),"Maior que CAP!",IF((DOLLAR(DV4+(VLOOKUP("PCS-OzTL500",ARBOR!$A:$C,3,0)*-TRUNC(DV4/VLOOKUP("PCS-OzTL500",ARBOR!$A:$C,3,0)-1,4)),6))<>(DOLLAR(VLOOKUP("PCS-OzTL500",ARBOR!$A:$C,3,0),6)),-TRUNC(DV4/VLOOKUP("PCS-OzTL500",ARBOR!$A:$C,3,0)-1,4)+0.0001,-TRUNC(DV4/VLOOKUP("PCS-OzTL500",ARBOR!$A:$C,3,0)-1,4))))) -> 0.0918 | DX4: =IF(DW4="S/Desc","S/Desc",IF(ISERROR(IF(DW4="","",VLOOKUP(($BC4&DW4&"Template desconto % Étnico nível conta"),BENEFICIOS!$A:$G,5,0))),"Criar",IF(DW4="","",VLOOKUP(($BC4&DW4&"Template desconto % Étnico nível conta"),BENEFICIOS!$A:$G,5,0)))) -> Criar | DZ4: =IF(DY4=0,"",IF(DY4=VLOOKUP("PCS-OzTL50",ARBOR!$A:$C,3,0),0.0001,IF(DY4>VLOOKUP("PCS-OzTL50",ARBOR!$A:$C,3,0),"Maior que CAP!",IF((DOLLAR(DY4+(VLOOKUP("PCS-OzTL50",ARBOR!$A:$C,3,0)*-TRUNC(DY4/VLOOKUP("PCS-OzTL50",ARBOR!$A:$C,3,0)-1,4)),6))<>(DOLLAR(VLOOKUP("PCS-OzTL50",ARBOR!$A:$C,3,0),6)),-TRUNC(DY4/VLOOKUP("PCS-OzTL50",ARBOR!$A:$C,3,0)-1,4)+0.0001,-TRUNC(DY4/VLOOKUP("PCS-OzTL50",ARBOR!$A:$C,3,0)-1,4))))) | EC4: =IF(EB4=0,"",IF(EB4=VLOOKUP("PCS-OzTL51",ARBOR!$A:$C,3,0),0.0001,IF(EB4>VLOOKUP("PCS-OzTL51",ARBOR!$A:$C,3,0),"Maior que CAP!",IF((DOLLAR(EB4+(VLOOKUP("PCS-OzTL51",ARBOR!$A:$C,3,0)*-TRUNC(EB4/VLOOKUP("PCS-OzTL51",ARBOR!$A:$C,3,0)-1,4)),6))<>(DOLLAR(VLOOKUP("PCS-OzTL51",ARBOR!$A:$C,3,0),6)),-TRUNC(EB4/VLOOKUP("PCS-OzTL51",ARBOR!$A:$C,3,0)-1,4)+0.0001,-TRUNC(EB4/VLOOKUP("PCS-OzTL51",ARBOR!$A:$C,3,0)-1,4))))) | EF4: =IF(EE4=0,"",IF(EE4=VLOOKUP("PCS-OzTL52",ARBOR!$A:$C,3,0),0.0001,IF(EE4>VLOOKUP("PCS-OzTL52",ARBOR!$A:$C,3,0),"Maior que CAP!",IF((DOLLAR(EE4+(VLOOKUP("PCS-OzTL52",ARBOR!$A:$C,3,0)*-TRUNC(EE4/VLOOKUP("PCS-OzTL52",ARBOR!$A:$C,3,0)-1,4)),6))<>(DOLLAR(VLOOKUP("PCS-OzTL52",ARBOR!$A:$C,3,0),6)),-TRUNC(EE4/VLOOKUP("PCS-OzTL52",ARBOR!$A:$C,3,0)-1,4)+0.0001,-TRUNC(EE4/VLOOKUP("PCS-OzTL52",ARBOR!$A:$C,3,0)-1,4))))) | EI4: =IF(EH4=0,"",IF(EH4=VLOOKUP("PCS-OzTL53",ARBOR!$A:$C,3,0),0.0001,IF(EH4>VLOOKUP("PCS-OzTL53",ARBOR!$A:$C,3,0),"Maior que CAP!",IF((DOLLAR(EH4+(VLOOKUP("PCS-OzTL53",ARBOR!$A:$C,3,0)*-TRUNC(EH4/VLOOKUP("PCS-OzTL53",ARBOR!$A:$C,3,0)-1,4)),6))<>(DOLLAR(VLOOKUP("PCS-OzTL53",ARBOR!$A:$C,3,0),6)),-TRUNC(EH4/VLOOKUP("PCS-OzTL53",ARBOR!$A:$C,3,0)-1,4)+0.0001,-TRUNC(EH4/VLOOKUP("PCS-OzTL53",ARBOR!$A:$C,3,0)-1,4))))) | EL4: =IF(EK4=0,"",IF(EK4=VLOOKUP("PCS-OzTL54",ARBOR!$A:$C,3,0),0.0001,IF(EK4>VLOOKUP("PCS-OzTL54",ARBOR!$A:$C,3,0),"Maior que CAP!",IF((DOLLAR(EK4+(VLOOKUP("PCS-OzTL54",ARBOR!$A:$C,3,0)*-TRUNC(EK4/VLOOKUP("PCS-OzTL54",ARBOR!$A:$C,3,0)-1,4)),6))<>(DOLLAR(VLOOKUP("PCS-OzTL54",ARBOR!$A:$C,3,0),6)),-TRUNC(EK4/VLOOKUP("PCS-OzTL54",ARBOR!$A:$C,3,0)-1,4)+0.0001,-TRUNC(EK4/VLOOKUP("PCS-OzTL54",ARBOR!$A:$C,3,0)-1,4))))) | EN4: 24.9 | EO4: =IF(EN4=0,"",IF(EN4=VLOOKUP("PCS-OzTL99",ARBOR!$A:$C,3,0),0.0001,IF(EN4>VLOOKUP("PCS-OzTL99",ARBOR!$A:$C,3,0),"Maior que CAP!",IF((DOLLAR(EN4+(VLOOKUP("PCS-OzTL99",ARBOR!$A:$C,3,0)*-TRUNC(EN4/VLOOKUP("PCS-OzTL99",ARBOR!$A:$C,3,0)-1,4)),6))<>(DOLLAR(VLOOKUP("PCS-OzTL99",ARBOR!$A:$C,3,0),6)),-TRUNC(EN4/VLOOKUP("PCS-OzTL99",ARBOR!$A:$C,3,0)-1,4)+0.0001,-TRUNC(EN4/VLOOKUP("PCS-OzTL99",ARBOR!$A:$C,3,0)-1,4))))) -> 0.1673 | EP4: =IF(EO4="S/Desc","S/Desc",IF(ISERROR(IF(EO4="","",VLOOKUP(($BC4&EO4&"Template desconto % Ponto adicional nível conta"),BENEFICIOS!$A:$G,5,0))),"Criar",IF(EO4="","",VLOOKUP(($BC4&EO4&"Template desconto % Ponto adicional nível conta"),BENEFICIOS!$A:$G,5,0)))) -> Criar | ER4: =IF(EQ4="Sim","PCS-34704","") | ES4: Sim | ET4: Benefício | EU4: 499 | EV4: 12 | EW4: =IF(ET4="Benefício","Oi benefício fidelização Multiprodutos","") -> Oi benefício fidelização Multiprodutos | EX4: =IF(ET4="Benefício","PCS-Fk83324","") -> PCS-Fk83324 | EY4: =IF(ES4="Sim","PCS-SBL553142","") -> PCS-SBL553142 | EZ4: LD + VC Oi | FA4: 0T0T_FTV_MIN_LD_270000. | FG4: =IF($BH4="","",$BH4+$BE4) | FH4: =IF($BK4="","",$BK4+$BE4) -> 154.9 | FI4: =IF($BN4="","",$BN4+$BE4) | FJ4: =IF($BQ4="","",$BQ4+$BE4) | FK4: =IF($BT4="","",$BT4+$BE4) | FL4: =IF($BW4="","",$BW4+$BE4) | FM4: =IF($BZ4="","",$BZ4+$BE4) | FN4: =IF($CC4="","",$CC4+$BE4) | FO4: =IF($CF4="","",$CF4+$BE4) | FP4: =IF($CI4="","",$CI4+$BE4) -> 164.9 | FQ4: =IF($CL4="","",$CL4+$BE4) | FR4: =IF($CO4="","",$CO4+$BE4) | FS4: =IF($CR4="","",$CR4+$BE4) | FT4: =IF($CU4="","",$CU4+$BE4) -> 184.9 | FU4: =IF($CX4="","",$CX4+$BE4) | FV4: =IF($DA4="","",$DA4+$BE4) | FW4: =IF($DD4="","",$DD4+$BE4)
