Workbook

Sheet DDD
B2: UF | C2: LOCALIDADE | D2: MUNICÍPIO | E2: Chave | F2: DDD | G2: UF
B3: AC | C3: ACRELÂNDIA | D3: ACRELANDIA | E3: =B3&D3 -> ACACRELANDIA | F3: 68 | G3: AC
B4: AC | C4: ASSIS BRASIL | D4: ASSIS BRASIL | E4: =B4&D4 -> ACASSIS BRASIL | F4: 68 | G4: AC
B5: AC | C5: BRASILÉIA | D5: BRASILEIA | E5: =B5&D5 -> ACBRASILEIA | F5: 68 | G5: AC
B6: AC | C6: BUJARI | D6: BUJARI | E6: =B6&D6 -> ACBUJARI | F6: 68 | G6: AC
B7: AC | C7: CAPIXABA | D7: CAPIXABA | E7: =B7&D7 -> ACCAPIXABA | F7: 68 | G7: AC
B8: AC | C8: ASSIS BRASIL | D8: CRUZEIRO DO SUL | E8: =B8&D8 -> ACCRUZEIRO DO SUL | F8: 68 | G8: AC
B9: AC | C9: CRUZEIRO DO SUL | D9: CRUZEIRO DO SUL | E9: =B9&D9 -> ACCRUZEIRO DO SUL | F9: 68 | G9: AC
B10: AC | C10: SANTA ROSA DO JURUA | D10: CRUZEIRO DO SUL | E10: =B10&D10 -> ACCRUZEIRO DO SUL | F10: 68 | G10: AC
B11: AC | C11: FEIJÓ | D11: FEIJO | E11: =B11&D11 -> ACFEIJO | F11: 68 | G11: AC
B12: AC | C12: JORDÃO | D12: JORDAO | E12: =B12&D12 -> ACJORDAO | F12: 68 | G12: AC
B13: AC | C13: MÂNCIO LIMA | D13: MANCIO LIMA | E13: =B13&D13 -> ACMANCIO LIMA | F13: 68 | G13: AC
B14: AC | C14: MANOEL URBANO | D14: MANOEL URBANO | E14: =B14&D14 -> ACMANOEL URBANO | F14: 68 | G14: AC
... B9183: TO | C9183: XAMBIOÁ | D9183: XAMBIOA | E9183: =B9183&D9183 -> TOXAMBIOA | F9183: 63 | G9183: TO

Sheet Exportar Planilha Final
A1: UF | B1: NO_MUNICIPIO | C1: GRUPO_OFERTA | D1: GRUPO_PORTA_OCIOSAS | E1: DT_CRIACAO | F1: Num_DDD
A2: AC | B2: Acrelandia | C2: CONEC LIGHT | D2: PO | E2: 08/10/2019 | F2: 68 | H2: INSERT INTO PEGARULES.TB_MUNICIPIOS_OFERTAS VALUES( | I2: =_xlfn.CONCAT("'",A2,"'",",") -> 'AC', | J2: =_xlfn.CONCAT("'",B2,"'",",") -> 'Acrelandia', | K2: =_xlfn.CONCAT("'",C2,"'",",") -> 'CONEC LIGHT', | L2: =_xlfn.CONCAT("'",D2,"'",",") -> 'PO', | M2: =_xlfn.CONCAT("to_date('",E2,"','dd/mm/yyyy')",",") -> to_date('08/10/2019','dd/mm/yyyy'), | N2: =_xlfn.CONCAT(F2,");") -> 68); | P2: =_xlfn.CONCAT(H2:N2) -> INSERT INTO PEGARULES.TB_MUNICIPIOS_OFERTAS VALUES('AC','Acrelandia','CONEC LIGHT','PO',to_date('08/10/2019','dd/mm/yyyy'),68);
A3: AC | B3: Assis Brasil | C3: CONEC LIGHT | D3: PO | E3: 08/10/2019 | F3: 68 | H3: INSERT INTO PEGARULES.TB_MUNICIPIOS_OFERTAS VALUES( | I3: =_xlfn.CONCAT("'",A3,"'",",") -> 'AC', | J3: =_xlfn.CONCAT("'",B3,"'",",") -> 'Assis Brasil', | K3: =_xlfn.CONCAT("'",C3,"'",",") -> 'CONEC LIGHT', | L3: =_xlfn.CONCAT("'",D3,"'",",") -> 'PO', | M3: =_xlfn.CONCAT("to_date('",E3,"','dd/mm/yyyy')",",") -> to_date('08/10/2019','dd/mm/yyyy'), | N3: =_xlfn.CONCAT(F3,");") -> 68); | P3: =_xlfn.CONCAT(H3:N3) -> INSERT INTO PEGARULES.TB_MUNICIPIOS_OFERTAS VALUES('AC','Assis Brasil','CONEC LIGHT','PO',to_date('08/10/2019','dd/mm/yyyy'),68);
A4: AC | B4: Brasileia | C4: CONEC LIGHT | D4: PO | E4: 08/10/2019 | F4: 68 | H4: INSERT INTO PEGARULES.TB_MUNICIPIOS_OFERTAS VALUES( | I4: =_xlfn.CONCAT("'",A4,"'",",") -> 'AC', | J4: =_xlfn.CONCAT("'",B4,"'",",") -> 'Brasileia', | K4: =_xlfn.CONCAT("'",C4,"'",",") -> 'CONEC LIGHT', | L4: =_xlfn.CONCAT("'",D4,"'",",") -> 'PO', | M4: =_xlfn.CONCAT("to_date('",E4,"','dd/mm/yyyy')",",") -> to_date('08/10/2019','dd/mm/yyyy'), | N4: =_xlfn.CONCAT(F4,");") -> 68); | P4: =_xlfn.CONCAT(H4:N4) -> INSERT INTO PEGARULES.TB_MUNICIPIOS_OFERTAS VALUES('AC','Brasileia','CONEC LIGHT','PO',to_date('08/10/2019','dd/mm/yyyy'),68);
A5: AC | B5: Bujari | C5: CONEC LIGHT | D5: PO | E5: 08/10/2019 | F5: 68 | H5: INSERT INTO PEGARULES.TB_MUNICIPIOS_OFERTAS VALUES( | I5: =_xlfn.CONCAT("'",A5,"'",",") -> 'AC', | J5: =_xlfn.CONCAT("'",B5,"'",",") -> 'Bujari', | K5: =_xlfn.CONCAT("'",C5,"'",",") -> 'CONEC LIGHT', | L5: =_xlfn.CONCAT("'",D5,"'",",") -> 'PO', | M5: =_xlfn.CONCAT("to_date('",E5,"','dd/mm/yyyy')",",") -> to_date('08/10/2019','dd/mm/yyyy'), | N5: =_xlfn.CONCAT(F5,");") -> 68); | P5: =_xlfn.CONCAT(H5:N5) -> INSERT INTO PEGARULES.TB_MUNICIPIOS_OFERTAS VALUES('AC','Bujari','CONEC LIGHT','PO',to_date('08/10/2019','dd/mm/yyyy'),68);
A6: AC | B6: Capixaba | C6: CONEC LIGHT | D6: PO | E6: 08/10/2019 | F6: 68 | H6: INSERT INTO PEGARULES.TB_MUNICIPIOS_OFERTAS VALUES( | I6: =_xlfn.CONCAT("'",A6,"'",",") -> 'AC', | J6: =_xlfn.CONCAT("'",B6,"'",",") -> 'Capixaba', | K6: =_xlfn.CONCAT("'",C6,"'",",") -> 'CONEC LIGHT', | L6: =_xlfn.CONCAT("'",D6,"'",",") -> 'PO', | M6: =_xlfn.CONCAT("to_date('",E6,"','dd/mm/yyyy')",",") -> to_date('08/10/2019','dd/mm/yyyy'), | N6: =_xlfn.CONCAT(F6,");") -> 68); | P6: =_xlfn.CONCAT(H6:N6) -> INSERT INTO PEGARULES.TB_MUNICIPIOS_OFERTAS VALUES('AC','Capixaba','CONEC LIGHT','PO',to_date('08/10/2019','dd/mm/yyyy'),68);
A7: AC | B7: Cruzeiro do Sul | C7: CONEC LIGHT | D7: PO | E7: 08/10/2019 | F7: 68 | H7: INSERT INTO PEGARULES.TB_MUNICIPIOS_OFERTAS VALUES( | I7: =_xlfn.CONCAT("'",A7,"'",",") -> 'AC', | J7: =_xlfn.CONCAT("'",B7,"'",",") -> 'Cruzeiro do Sul', | K7: =_xlfn.CONCAT("'",C7,"'",",") -> 'CONEC LIGHT', | L7: =_xlfn.CONCAT("'",D7,"'",",") -> 'PO', | M7: =_xlfn.CONCAT("to_date('",E7,"','dd/mm/yyyy')",",") -> to_date('08/10/2019','dd/mm/yyyy'), | N7: =_xlfn.CONCAT(F7,");") -> 68); | P7: =_xlfn.CONCAT(H7:N7) -> INSERT INTO PEGARULES.TB_MUNICIPIOS_OFERTAS VALUES('AC','Cruzeiro do Sul','CONEC LIGHT','PO',to_date('08/10/2019','dd/mm/yyyy'),68);
A8: AC | B8: Epitaciolandia | D8: PO | E8: 08/10/2019 | F8: 68 | H8: INSERT INTO PEGARULES.TB_MUNICIPIOS_OFERTAS VALUES( | I8: =_xlfn.CONCAT("'",A8,"'",",") -> 'AC', | J8: =_xlfn.CONCAT("'",B8,"'",",") -> 'Epitaciolandia', | K8: =_xlfn.CONCAT("'",C8,"'",",") -> '', | L8: =_xlfn.CONCAT("'",D8,"'",",") -> 'PO', | M8: =_xlfn.CONCAT("to_date('",E8,"','dd/mm/yyyy')",",") -> to_date('08/10/2019','dd/mm/yyyy'), | N8: =_xlfn.CONCAT(F8,");") -> 68); | P8: =_xlfn.CONCAT(H8:N8) -> INSERT INTO PEGARULES.TB_MUNICIPIOS_OFERTAS VALUES('AC','Epitaciolandia','','PO',to_date('08/10/2019','dd/mm/yyyy'),68);
A9: AC | B9: Feijo | C9: CONEC LIGHT | D9: PO | E9: 08/10/2019 | F9: 68 | H9: INSERT INTO PEGARULES.TB_MUNICIPIOS_OFERTAS VALUES( | I9: =_xlfn.CONCAT("'",A9,"'",",") -> 'AC', | J9: =_xlfn.CONCAT("'",B9,"'",",") -> 'Feijo', | K9: =_xlfn.CONCAT("'",C9,"'",",") -> 'CONEC LIGHT', | L9: =_xlfn.CONCAT("'",D9,"'",",") -> 'PO', | M9: =_xlfn.CONCAT("to_date('",E9,"','dd/mm/yyyy')",",") -> to_date('08/10/2019','dd/mm/yyyy'), | N9: =_xlfn.CONCAT(F9,");") -> 68); | P9: =_xlfn.CONCAT(H9:N9) -> INSERT INTO PEGARULES.TB_MUNICIPIOS_OFERTAS VALUES('AC','Feijo','CONEC LIGHT','PO',to_date('08/10/2019','dd/mm/yyyy'),68);
A10: AC | B10: Jordao | C10: CONEC LIGHT | D10: PO | E10: 08/10/2019 | F10: 68 | H10: INSERT INTO PEGARULES.TB_MUNICIPIOS_OFERTAS VALUES( | I10: =_xlfn.CONCAT("'",A10,"'",",") -> 'AC', | J10: =_xlfn.CONCAT("'",B10,"'",",") -> 'Jordao', | K10: =_xlfn.CONCAT("'",C10,"'",",") -> 'CONEC LIGHT', | L10: =_xlfn.CONCAT("'",D10,"'",",") -> 'PO', | M10: =_xlfn.CONCAT("to_date('",E10,"','dd/mm/yyyy')",",") -> to_date('08/10/2019','dd/mm/yyyy'), | N10: =_xlfn.CONCAT(F10,");") -> 68); | P10: =_xlfn.CONCAT(H10:N10) -> INSERT INTO PEGARULES.TB_MUNICIPIOS_OFERTAS VALUES('AC','Jordao','CONEC LIGHT','PO',to_date('08/10/2019','dd/mm/yyyy'),68);
A11: AC | B11: Mancio Lima | C11: CONEC LIGHT | D11: PO | E11: 08/10/2019 | F11: 68 | H11: INSERT INTO PEGARULES.TB_MUNICIPIOS_OFERTAS VALUES( | I11: =_xlfn.CONCAT("'",A11,"'",",") -> 'AC', | J11: =_xlfn.CONCAT("'",B11,"'",",") -> 'Mancio Lima', | K11: =_xlfn.CONCAT("'",C11,"'",",") -> 'CONEC LIGHT', | L11: =_xlfn.CONCAT("'",D11,"'",",") -> 'PO', | M11: =_xlfn.CONCAT("to_date('",E11,"','dd/mm/yyyy')",",") -> to_date('08/10/2019','dd/mm/yyyy'), | N11: =_xlfn.CONCAT(F11,");") -> 68); | P11: =_xlfn.CONCAT(H11:N11) -> INSERT INTO PEGARULES.TB_MUNICIPIOS_OFERTAS VALUES('AC','Mancio Lima','CONEC LIGHT','PO',to_date('08/10/2019','dd/mm/yyyy'),68);
A12: AC | B12: Manoel Urbano | C12: CONEC LIGHT | D12: PO | E12: 08/10/2019 | F12: 68 | H12: INSERT INTO PEGARULES.TB_MUNICIPIOS_OFERTAS VALUES( | I12: =_xlfn.CONCAT("'",A12,"'",",") -> 'AC', | J12: =_xlfn.CONCAT("'",B12,"'",",") -> 'Manoel Urbano', | K12: =_xlfn.CONCAT("'",C12,"'",",") -> 'CONEC LIGHT', | L12: =_xlfn.CONCAT("'",D12,"'",",") -> 'PO', | M12: =_xlfn.CONCAT("to_date('",E12,"','dd/mm/yyyy')",",") -> to_date('08/10/2019','dd/mm/yyyy'), | N12: =_xlfn.CONCAT(F12,");") -> 68); | P12: =_xlfn.CONCAT(H12:N12) -> INSERT INTO PEGARULES.TB_MUNICIPIOS_OFERTAS VALUES('AC','Manoel Urbano','CONEC LIGHT','PO',to_date('08/10/2019','dd/mm/yyyy'),68);
A13: AC | B13: Marechal Thaumaturgo | C13: CONEC LIGHT | D13: PO | E13: 08/10/2019 | F13: 68 | H13: INSERT INTO PEGARULES.TB_MUNICIPIOS_OFERTAS VALUES( | I13: =_xlfn.CONCAT("'",A13,"'",",") -> 'AC', | J13: =_xlfn.CONCAT("'",B13,"'",",") -> 'Marechal Thaumaturgo', | K13: =_xlfn.CONCAT("'",C13,"'",",") -> 'CONEC LIGHT', | L13: =_xlfn.CONCAT("'",D13,"'",",") -> 'PO', | M13: =_xlfn.CONCAT("to_date('",E13,"','dd/mm/yyyy')",",") -> to_date('08/10/2019','dd/mm/yyyy'), | N13: =_xlfn.CONCAT(F13,");") -> 68); | P13: =_xlfn.CONCAT(H13:N13) -> INSERT INTO PEGARULES.TB_MUNICIPIOS_OFERTAS VALUES('AC','Marechal Thaumaturgo','CONEC LIGHT','PO',to_date('08/10/2019','dd/mm/yyyy'),68);
A14: AC | B14: Placido de Castro | C14: CONEC LIGHT | D14: PO | E14: 08/10/2019 | F14: 68 | H14: INSERT INTO PEGARULES.TB_MUNICIPIOS_OFERTAS VALUES( | I14: =_xlfn.CONCAT("'",A14,"'",",") -> 'AC', | J14: =_xlfn.CONCAT("'",B14,"'",",") -> 'Placido de Castro', | K14: =_xlfn.CONCAT("'",C14,"'",",") -> 'CONEC LIGHT', | L14: =_xlfn.CONCAT("'",D14,"'",",") -> 'PO', | M14: =_xlfn.CONCAT("to_date('",E14,"','dd/mm/yyyy')",",") -> to_date('08/10/2019','dd/mm/yyyy'), | N14: =_xlfn.CONCAT(F14,");") -> 68); | P14: =_xlfn.CONCAT(H14:N14) -> INSERT INTO PEGARULES.TB_MUNICIPIOS_OFERTAS VALUES('AC','Placido de Castro','CONEC LIGHT','PO',to_date('08/10/2019','dd/mm/yyyy'),68);
A15: AC | B15: Porto Acre | C15: CONEC LIGHT | D15: PO | E15: 08/10/2019 | F15: 68 | H15: INSERT INTO PEGARULES.TB_MUNICIPIOS_OFERTAS VALUES( | I15: =_xlfn.CONCAT("'",A15,"'",",") -> 'AC', | J15: =_xlfn.CONCAT("'",B15,"'",",") -> 'Porto Acre', | K15: =_xlfn.CONCAT("'",C15,"'",",") -> 'CONEC LIGHT', | L15: =_xlfn.CONCAT("'",D15,"'",",") -> 'PO', | M15: =_xlfn.CONCAT("to_date('",E15,"','dd/mm/yyyy')",",") -> to_date('08/10/2019','dd/mm/yyyy'), | N15: =_xlfn.CONCAT(F15,");") -> 68); | P15: =_xlfn.CONCAT(H15:N15) -> INSERT INTO PEGARULES.TB_MUNICIPIOS_OFERTAS VALUES('AC','Porto Acre','CONEC LIGHT','PO',to_date('08/10/2019','dd/mm/yyyy'),68);
A16: AC | B16: Porto Walter | C16: CONEC LIGHT | D16: PO | E16: 08/10/2019 | F16: 68 | H16: INSERT INTO PEGARULES.TB_MUNICIPIOS_OFERTAS VALUES( | I16: =_xlfn.CONCAT("'",A16,"'",",") -> 'AC', | J16: =_xlfn.CONCAT("'",B16,"'",",") -> 'Porto Walter', | K16: =_xlfn.CONCAT("'",C16,"'",",") -> 'CONEC LIGHT', | L16: =_xlfn.CONCAT("'",D16,"'",",") -> 'PO', | M16: =_xlfn.CONCAT("to_date('",E16,"','dd/mm/yyyy')",",") -> to_date('08/10/2019','dd/mm/yyyy'), | N16: =_xlfn.CONCAT(F16,");") -> 68); | P16: =_xlfn.CONCAT(H16:N16) -> INSERT INTO PEGARULES.TB_MUNICIPIOS_OFERTAS VALUES('AC','Porto Walter','CONEC LIGHT','PO',to_date('08/10/2019','dd/mm/yyyy'),68);
A17: AC | B17: Rio Branco | C17: CONEC LIGHT | E17: 08/10/2019 | F17: 68 | H17: INSERT INTO PEGARULES.TB_MUNICIPIOS_OFERTAS VALUES( | I17: =_xlfn.CONCAT("'",A17,"'",",") -> 'AC', | J17: =_xlfn.CONCAT("'",B17,"'",",") -> 'Rio Branco', | K17: =_xlfn.CONCAT("'",C17,"'",",") -> 'CONEC LIGHT', | L17: =_xlfn.CONCAT("'",D17,"'",",") -> '', | M17: =_xlfn.CONCAT("to_date('",E17,"','dd/mm/yyyy')",",") -> to_date('08/10/2019','dd/mm/yyyy'), | N17: =_xlfn.CONCAT(F17,");") -> 68); | P17: =_xlfn.CONCAT(H17:N17) -> INSERT INTO PEGARULES.TB_MUNICIPIOS_OFERTAS VALUES('AC','Rio Branco','CONEC LIGHT','',to_date('08/10/2019','dd/mm/yyyy'),68);
A18: AC | B18: Rodrigues Alves | C18: CONEC LIGHT | D18: PO | E18: 08/10/2019 | F18: 68 | H18: INSERT INTO PEGARULES.TB_MUNICIPIOS_OFERTAS VALUES( | I18: =_xlfn.CONCAT("'",A18,"'",",") -> 'AC', | J18: =_xlfn.CONCAT("'",B18,"'",",") -> 'Rodrigues Alves', | K18: =_xlfn.CONCAT("'",C18,"'",",") -> 'CONEC LIGHT', | L18: =_xlfn.CONCAT("'",D18,"'",",") -> 'PO', | M18: =_xlfn.CONCAT("to_date('",E18,"','dd/mm/yyyy')",",") -> to_date('08/10/2019','dd/mm/yyyy'), | N18: =_xlfn.CONCAT(F18,");") -> 68); | P18: =_xlfn.CONCAT(H18:N18) -> INSERT INTO PEGARULES.TB_MUNICIPIOS_OFERTAS VALUES('AC','Rodrigues Alves','CONEC LIGHT','PO',to_date('08/10/2019','dd/mm/yyyy'),68);
A19: AC | B19: Santa Rosa do Purus | C19: CONEC LIGHT | D19: PO | E19: 08/10/2019 | F19: 68 | H19: INSERT INTO PEGARULES.TB_MUNICIPIOS_OFERTAS VALUES( | I19: =_xlfn.CONCAT("'",A19,"'",",") -> 'AC', | J19: =_xlfn.CONCAT("'",B19,"'",",") -> 'Santa Rosa do Purus', | K19: =_xlfn.CONCAT("'",C19,"'",",") -> 'CONEC LIGHT', | L19: =_xlfn.CONCAT("'",D19,"'",",") -> 'PO', | M19: =_xlfn.CONCAT("to_date('",E19,"','dd/mm/yyyy')",",") -> to_date('08/10/2019','dd/mm/yyyy'), | N19: =_xlfn.CONCAT(F19,");") -> 68); | P19: =_xlfn.CONCAT(H19:N19) -> INSERT INTO PEGARULES.TB_MUNICIPIOS_OFERTAS VALUES('AC','Santa Rosa do Purus','CONEC LIGHT','PO',to_date('08/10/2019','dd/mm/yyyy'),68);
A20: AC | B20: Sena Madureira | C20: CONEC LIGHT | D20: PO | E20: 08/10/2019 | F20: 68 | H20: INSERT INTO PEGARULES.TB_MUNICIPIOS_OFERTAS VALUES( | I20: =_xlfn.CONCAT("'",A20,"'",",") -> 'AC', | J20: =_xlfn.CONCAT("'",B20,"'",",") -> 'Sena Madureira', | K20: =_xlfn.CONCAT("'",C20,"'",",") -> 'CONEC LIGHT', | L20: =_xlfn.CONCAT("'",D20,"'",",") -> 'PO', | M20: =_xlfn.CONCAT("to_date('",E20,"','dd/mm/yyyy')",",") -> to_date('08/10/2019','dd/mm/yyyy'), | N20: =_xlfn.CONCAT(F20,");") -> 68); | P20: =_xlfn.CONCAT(H20:N20) -> INSERT INTO PEGARULES.TB_MUNICIPIOS_OFERTAS VALUES('AC','Sena Madureira','CONEC LIGHT','PO',to_date('08/10/2019','dd/mm/yyyy'),68);
A21: AC | B21: Senador Guiomard | C21: CONEC LIGHT | D21: PO | E21: 08/10/2019 | F21: 68 | H21: INSERT INTO PEGARULES.TB_MUNICIPIOS_OFERTAS VALUES( | I21: =_xlfn.CONCAT("'",A21,"'",",") -> 'AC', | J21: =_xlfn.CONCAT("'",B21,"'",",") -> 'Senador Guiomard', | K21: =_xlfn.CONCAT("'",C21,"'",",") -> 'CONEC LIGHT', | L21: =_xlfn.CONCAT("'",D21,"'",",") -> 'PO', | M21: =_xlfn.CONCAT("to_date('",E21,"','dd/mm/yyyy')",",") -> to_date('08/10/2019','dd/mm/yyyy'), | N21: =_xlfn.CONCAT(F21,");") -> 68); | P21: =_xlfn.CONCAT(H21:N21) -> INSERT INTO PEGARULES.TB_MUNICIPIOS_OFERTAS VALUES('AC','Senador Guiomard','CONEC LIGHT','PO',to_date('08/10/2019','dd/mm/yyyy'),68);
A22: AC | B22: Tarauaca | C22: CONEC LIGHT | D22: PO | E22: 08/10/2019 | F22: 68 | H22: INSERT INTO PEGARULES.TB_MUNICIPIOS_OFERTAS VALUES( | I22: =_xlfn.CONCAT("'",A22,"'",",") -> 'AC', | J22: =_xlfn.CONCAT("'",B22,"'",",") -> 'Tarauaca', | K22: =_xlfn.CONCAT("'",C22,"'",",") -> 'CONEC LIGHT', | L22: =_xlfn.CONCAT("'",D22,"'",",") -> 'PO', | M22: =_xlfn.CONCAT("to_date('",E22,"','dd/mm/yyyy')",",") -> to_date('08/10/2019','dd/mm/yyyy'), | N22: =_xlfn.CONCAT(F22,");") -> 68); | P22: =_xlfn.CONCAT(H22:N22) -> INSERT INTO PEGARULES.TB_MUNICIPIOS_OFERTAS VALUES('AC','Tarauaca','CONEC LIGHT','PO',to_date('08/10/2019','dd/mm/yyyy'),68);
A23: AC | B23: Xapuri | C23: CONEC LIGHT | D23: PO | E23: 08/10/2019 | F23: 68 | H23: INSERT INTO PEGARULES.TB_MUNICIPIOS_OFERTAS VALUES( | I23: =_xlfn.CONCAT("'",A23,"'",",") -> 'AC', | J23: =_xlfn.CONCAT("'",B23,"'",",") -> 'Xapuri', | K23: =_xlfn.CONCAT("'",C23,"'",",") -> 'CONEC LIGHT', | L23: =_xlfn.CONCAT("'",D23,"'",",") -> 'PO', | M23: =_xlfn.CONCAT("to_date('",E23,"','dd/mm/yyyy')",",") -> to_date('08/10/2019','dd/mm/yyyy'), | N23: =_xlfn.CONCAT(F23,");") -> 68); | P23: =_xlfn.CONCAT(H23:N23) -> INSERT INTO PEGARULES.TB_MUNICIPIOS_OFERTAS VALUES('AC','Xapuri','CONEC LIGHT','PO',to_date('08/10/2019','dd/mm/yyyy'),68);
A24: AL | B24: agua Branca | D24: PO | E24: 08/10/2019 | F24: 82 | H24: INSERT INTO PEGARULES.TB_MUNICIPIOS_OFERTAS VALUES( | I24: =_xlfn.CONCAT("'",A24,"'",",") -> 'AL', | J24: =_xlfn.CONCAT("'",B24,"'",",") -> 'agua Branca', | K24: =_xlfn.CONCAT("'",C24,"'",",") -> '', | L24: =_xlfn.CONCAT("'",D24,"'",",") -> 'PO', | M24: =_xlfn.CONCAT("to_date('",E24,"','dd/mm/yyyy')",",") -> to_date('08/10/2019','dd/mm/yyyy'), | N24: =_xlfn.CONCAT(F24,");") -> 82); | P24: =_xlfn.CONCAT(H24:N24) -> INSERT INTO PEGARULES.TB_MUNICIPIOS_OFERTAS VALUES('AL','agua Branca','','PO',to_date('08/10/2019','dd/mm/yyyy'),82);
A25: AL | B25: Anadia | D25: PO | E25: 08/10/2019 | F25: 82 | H25: INSERT INTO PEGARULES.TB_MUNICIPIOS_OFERTAS VALUES( | I25: =_xlfn.CONCAT("'",A25,"'",",") -> 'AL', | J25: =_xlfn.CONCAT("'",B25,"'",",") -> 'Anadia', | K25: =_xlfn.CONCAT("'",C25,"'",",") -> '', | L25: =_xlfn.CONCAT("'",D25,"'",",") -> 'PO', | M25: =_xlfn.CONCAT("to_date('",E25,"','dd/mm/yyyy')",",") -> to_date('08/10/2019','dd/mm/yyyy'), | N25: =_xlfn.CONCAT(F25,");") -> 82); | P25: =_xlfn.CONCAT(H25:N25) -> INSERT INTO PEGARULES.TB_MUNICIPIOS_OFERTAS VALUES('AL','Anadia','','PO',to_date('08/10/2019','dd/mm/yyyy'),82);
A26: AL | B26: Arapiraca | C26: BL | D26: PO | E26: 08/10/2019 | F26: 82 | H26: INSERT INTO PEGARULES.TB_MUNICIPIOS_OFERTAS VALUES( | I26: =_xlfn.CONCAT("'",A26,"'",",") -> 'AL', | J26: =_xlfn.CONCAT("'",B26,"'",",") -> 'Arapiraca', | K26: =_xlfn.CONCAT("'",C26,"'",",") -> 'BL', | L26: =_xlfn.CONCAT("'",D26,"'",",") -> 'PO', | M26: =_xlfn.CONCAT("to_date('",E26,"','dd/mm/yyyy')",",") -> to_date('08/10/2019','dd/mm/yyyy'), | N26: =_xlfn.CONCAT(F26,");") -> 82); | P26: =_xlfn.CONCAT(H26:N26) -> INSERT INTO PEGARULES.TB_MUNICIPIOS_OFERTAS VALUES('AL','Arapiraca','BL','PO',to_date('08/10/2019','dd/mm/yyyy'),82);
A27: AL | B27: Atalaia | D27: PO | E27: 08/10/2019 | F27: 82 | H27: INSERT INTO PEGARULES.TB_MUNICIPIOS_OFERTAS VALUES( | I27: =_xlfn.CONCAT("'",A27,"'",",") -> 'AL', | J27: =_xlfn.CONCAT("'",B27,"'",",") -> 'Atalaia', | K27: =_xlfn.CONCAT("'",C27,"'",",") -> '', | L27: =_xlfn.CONCAT("'",D27,"'",",") -> 'PO', | M27: =_xlfn.CONCAT("to_date('",E27,"','dd/mm/yyyy')",",") -> to_date('08/10/2019','dd/mm/yyyy'), | N27: =_xlfn.CONCAT(F27,");") -> 82); | P27: =_xlfn.CONCAT(H27:N27) -> INSERT INTO PEGARULES.TB_MUNICIPIOS_OFERTAS VALUES('AL','Atalaia','','PO',to_date('08/10/2019','dd/mm/yyyy'),82);
A28: AL | B28: Barra de Santo Antonio | D28: PO | E28: 08/10/2019 | F28: 82 | H28: INSERT INTO PEGARULES.TB_MUNICIPIOS_OFERTAS VALUES( | I28: =_xlfn.CONCAT("'",A28,"'",",") -> 'AL', | J28: =_xlfn.CONCAT("'",B28,"'",",") -> 'Barra de Santo Antonio', | K28: =_xlfn.CONCAT("'",C28,"'",",") -> '', | L28: =_xlfn.CONCAT("'",D28,"'",",") -> 'PO', | M28: =_xlfn.CONCAT("to_date('",E28,"','dd/mm/yyyy')",",") -> to_date('08/10/2019','dd/mm/yyyy'), | N28: =_xlfn.CONCAT(F28,");") -> 82); | P28: =_xlfn.CONCAT(H28:N28) -> INSERT INTO PEGARULES.TB_MUNICIPIOS_OFERTAS VALUES('AL','Barra de Santo Antonio','','PO',to_date('08/10/2019','dd/mm/yyyy'),82);
A29: AL | B29: Barra de Sao Miguel | D29: PO | E29: 08/10/2019 | F29: 82 | H29: INSERT INTO PEGARULES.TB_MUNICIPIOS_OFERTAS VALUES( | I29: =_xlfn.CONCAT("'",A29,"'",",") -> 'AL', | J29: =_xlfn.CONCAT("'",B29,"'",",") -> 'Barra de Sao Miguel', | K29: =_xlfn.CONCAT("'",C29,"'",",") -> '', | L29: =_xlfn.CONCAT("'",D29,"'",",") -> 'PO', | M29: =_xlfn.CONCAT("to_date('",E29,"','dd/mm/yyyy')",",") -> to_date('08/10/2019','dd/mm/yyyy'), | N29: =_xlfn.CONCAT(F29,");") -> 82); | P29: =_xlfn.CONCAT(H29:N29) -> INSERT INTO PEGARULES.TB_MUNICIPIOS_OFERTAS VALUES('AL','Barra de Sao Miguel','','PO',to_date('08/10/2019','dd/mm/yyyy'),82);
A30: AL | B30: Batalha | D30: PO | E30: 08/10/2019 | F30: 82 | H30: INSERT INTO PEGARULES.TB_MUNICIPIOS_OFERTAS VALUES( | I30: =_xlfn.CONCAT("'",A30,"'",",") -> 'AL', | J30: =_xlfn.CONCAT("'",B30,"'",",") -> 'Batalha', | K30: =_xlfn.CONCAT("'",C30,"'",",") -> '', | L30: =_xlfn.CONCAT("'",D30,"'",",") -> 'PO', | M30: =_xlfn.CONCAT("to_date('",E30,"','dd/mm/yyyy')",",") -> to_date('08/10/2019','dd/mm/yyyy'), | N30: =_xlfn.CONCAT(F30,");") -> 82); | P30: =_xlfn.CONCAT(H30:N30) -> INSERT INTO PEGARULES.TB_MUNICIPIOS_OFERTAS VALUES('AL','Batalha','','PO',to_date('08/10/2019','dd/mm/yyyy'),82);
A31: AL | B31: Belem | D31: PO | E31: 08/10/2019 | F31: 82 | H31: INSERT INTO PEGARULES.TB_MUNICIPIOS_OFERTAS VALUES( | I31: =_xlfn.CONCAT("'",A31,"'",",") -> 'AL', | J31: =_xlfn.CONCAT("'",B31,"'",",") -> 'Belem', | K31: =_xlfn.CONCAT("'",C31,"'",",") -> '', | L31: =_xlfn.CONCAT("'",D31,"'",",") -> 'PO', | M31: =_xlfn.CONCAT("to_date('",E31,"','dd/mm/yyyy')",",") -> to_date('08/10/2019','dd/mm/yyyy'), | N31: =_xlfn.CONCAT(F31,");") -> 82); | P31: =_xlfn.CONCAT(H31:N31) -> INSERT INTO PEGARULES.TB_MUNICIPIOS_OFERTAS VALUES('AL','Belem','','PO',to_date('08/10/2019','dd/mm/yyyy'),82);
A32: AL | B32: Belo Monte | D32: PO | E32: 08/10/2019 | F32: 82 | H32: INSERT INTO PEGARULES.TB_MUNICIPIOS_OFERTAS VALUES( | I32: =_xlfn.CONCAT("'",A32,"'",",") -> 'AL', | J32: =_xlfn.CONCAT("'",B32,"'",",") -> 'Belo Monte', | K32: =_xlfn.CONCAT("'",C32,"'",",") -> '', | L32: =_xlfn.CONCAT("'",D32,"'",",") -> 'PO', | M32: =_xlfn.CONCAT("to_date('",E32,"','dd/mm/yyyy')",",") -> to_date('08/10/2019','dd/mm/yyyy'), | N32: =_xlfn.CONCAT(F32,");") -> 82); | P32: =_xlfn.CONCAT(H32:N32) -> INSERT INTO PEGARULES.TB_MUNICIPIOS_OFERTAS VALUES('AL','Belo Monte','','PO',to_date('08/10/2019','dd/mm/yyyy'),82);
A33: AL | B33: Boca da Mata | D33: PO | E33: 08/10/2019 | F33: 82 | H33: INSERT INTO PEGARULES.TB_MUNICIPIOS_OFERTAS VALUES( | I33: =_xlfn.CONCAT("'",A33,"'",",") -> 'AL', | J33: =_xlfn.CONCAT("'",B33,"'",",") -> 'Boca da Mata', | K33: =_xlfn.CONCAT("'",C33,"'",",") -> '', | L33: =_xlfn.CONCAT("'",D33,"'",",") -> 'PO', | M33: =_xlfn.CONCAT("to_date('",E33,"','dd/mm/yyyy')",",") -> to_date('08/10/2019','dd/mm/yyyy'), | N33: =_xlfn.CONCAT(F33,");") -> 82); | P33: =_xlfn.CONCAT(H33:N33) -> INSERT INTO PEGARULES.TB_MUNICIPIOS_OFERTAS VALUES('AL','Boca da Mata','','PO',to_date('08/10/2019','dd/mm/yyyy'),82);
A34: AL | B34: Branquinha | D34: PO | E34: 08/10/2019 | F34: 82 | H34: INSERT INTO PEGARULES.TB_MUNICIPIOS_OFERTAS VALUES( | I34: =_xlfn.CONCAT("'",A34,"'",",") -> 'AL', | J34: =_xlfn.CONCAT("'",B34,"'",",") -> 'Branquinha', | K34: =_xlfn.CONCAT("'",C34,"'",",") -> '', | L34: =_xlfn.CONCAT("'",D34,"'",",") -> 'PO', | M34: =_xlfn.CONCAT("to_date('",E34,"','dd/mm/yyyy')",",") -> to_date('08/10/2019','dd/mm/yyyy'), | N34: =_xlfn.CONCAT(F34,");") -> 82); | P34: =_xlfn.CONCAT(H34:N34) -> INSERT INTO PEGARULES.TB_MUNICIPIOS_OFERTAS VALUES('AL','Branquinha','','PO',to_date('08/10/2019','dd/mm/yyyy'),82);
A35: AL | B35: Cacimbinhas | D35: PO | E35: 08/10/2019 | F35: 82 | H35: INSERT INTO PEGARULES.TB_MUNICIPIOS_OFERTAS VALUES( | I35: =_xlfn.CONCAT("'",A35,"'",",") -> 'AL', | J35: =_xlfn.CONCAT("'",B35,"'",",") -> 'Cacimbinhas', | K35: =_xlfn.CONCAT("'",C35,"'",",") -> '', | L35: =_xlfn.CONCAT("'",D35,"'",",") -> 'PO', | M35: =_xlfn.CONCAT("to_date('",E35,"','dd/mm/yyyy')",",") -> to_date('08/10/2019','dd/mm/yyyy'), | N35: =_xlfn.CONCAT(F35,");") -> 82); | P35: =_xlfn.CONCAT(H35:N35) -> INSERT INTO PEGARULES.TB_MUNICIPIOS_OFERTAS VALUES('AL','Cacimbinhas','','PO',to_date('08/10/2019','dd/mm/yyyy'),82);
A36: AL | B36: Cajueiro | D36: PO | E36: 08/10/2019 | F36: 82 | H36: INSERT INTO PEGARULES.TB_MUNICIPIOS_OFERTAS VALUES( | I36: =_xlfn.CONCAT("'",A36,"'",",") -> 'AL', | J36: =_xlfn.CONCAT("'",B36,"'",",") -> 'Cajueiro', | K36: =_xlfn.CONCAT("'",C36,"'",",") -> '', | L36: =_xlfn.CONCAT("'",D36,"'",",") -> 'PO', | M36: =_xlfn.CONCAT("to_date('",E36,"','dd/mm/yyyy')",",") -> to_date('08/10/2019','dd/mm/yyyy'), | N36: =_xlfn.CONCAT(F36,");") -> 82); | P36: =_xlfn.CONCAT(H36:N36) -> INSERT INTO PEGARULES.TB_MUNICIPIOS_OFERTAS VALUES('AL','Cajueiro','','PO',to_date('08/10/2019','dd/mm/yyyy'),82);
A37: AL | B37: Campestre | D37: PO | E37: 08/10/2019 | F37: 82 | H37: INSERT INTO PEGARULES.TB_MUNICIPIOS_OFERTAS VALUES( | I37: =_xlfn.CONCAT("'",A37,"'",",") -> 'AL', | J37: =_xlfn.CONCAT("'",B37,"'",",") -> 'Campestre', | K37: =_xlfn.CONCAT("'",C37,"'",",") -> '', | L37: =_xlfn.CONCAT("'",D37,"'",",") -> 'PO', | M37: =_xlfn.CONCAT("to_date('",E37,"','dd/mm/yyyy')",",") -> to_date('08/10/2019','dd/mm/yyyy'), | N37: =_xlfn.CONCAT(F37,");") -> 82); | P37: =_xlfn.CONCAT(H37:N37) -> INSERT INTO PEGARULES.TB_MUNICIPIOS_OFERTAS VALUES('AL','Campestre','','PO',to_date('08/10/2019','dd/mm/yyyy'),82);
A38: AL | B38: Campo Alegre | D38: PO | E38: 08/10/2019 | F38: 82 | H38: INSERT INTO PEGARULES.TB_MUNICIPIOS_OFERTAS VALUES( | I38: =_xlfn.CONCAT("'",A38,"'",",") -> 'AL', | J38: =_xlfn.CONCAT("'",B38,"'",",") -> 'Campo Alegre', | K38: =_xlfn.CONCAT("'",C38,"'",",") -> '', | L38: =_xlfn.CONCAT("'",D38,"'",",") -> 'PO', | M38: =_xlfn.CONCAT("to_date('",E38,"','dd/mm/yyyy')",",") -> to_date('08/10/2019','dd/mm/yyyy'), | N38: =_xlfn.CONCAT(F38,");") -> 82); | P38: =_xlfn.CONCAT(H38:N38) -> INSERT INTO PEGARULES.TB_MUNICIPIOS_OFERTAS VALUES('AL','Campo Alegre','','PO',to_date('08/10/2019','dd/mm/yyyy'),82);
... A48: AL | B48: Craibas | D48: PO | E48: 08/10/2019 | F48: 82 | H48: INSERT INTO PEGARULES.TB_MUNICIPIOS_OFERTAS VALUES( | I48: =_xlfn.CONCAT("'",A48,"'",",") -> 'AL', | J48: =_xlfn.CONCAT("'",B48,"'",",") -> 'Craibas', | K48: =_xlfn.CONCAT("'",C48,"'",",") -> '', | L48: =_xlfn.CONCAT("'",D48,"'",",") -> 'PO', | M48: =_xlfn.CONCAT("to_date('",E48,"','dd/mm/yyyy')",",") -> to_date('08/10/2019','dd/mm/yyyy'), | N48: =_xlfn.CONCAT(F48,");") -> 82); | P48: =_xlfn.CONCAT(H48:N48) -> INSERT INTO PEGARULES.TB_MUNICIPIOS_OFERTAS VALUES('AL','Craibas','','PO',to_date('08/10/2019','dd/mm/yyyy'),82);
A49: AL | B49: Delmiro Gouveia | C49: BL | D49: PO | E49: 08/10/2019 | F49: 82 | H49: INSERT INTO PEGARULES.TB_MUNICIPIOS_OFERTAS VALUES( | I49: =_xlfn.CONCAT("'",A49,"'",",") -> 'AL', | J49: =_xlfn.CONCAT("'",B49,"'",",") -> 'Delmiro Gouveia', | K49: =_xlfn.CONCAT("'",C49,"'",",") -> 'BL', | L49: =_xlfn.CONCAT("'",D49,"'",",") -> 'PO', | M49: =_xlfn.CONCAT("to_date('",E49,"','dd/mm/yyyy')",",") -> to_date('08/10/2019','dd/mm/yyyy'), | N49: =_xlfn.CONCAT(F49,");") -> 82); | P49: =_xlfn.CONCAT(H49:N49) -> INSERT INTO PEGARULES.TB_MUNICIPIOS_OFERTAS VALUES('AL','Delmiro Gouveia','BL','PO',to_date('08/10/2019','dd/mm/yyyy'),82);
...

Sheet Sheet3
A1: select replace(no_municipio,'''''',chr(39)) as no_municipio from PEGARULES.TB_MUNICIPIOS_OFERTAS
A2: where no_municipio like '%''%';
A3: update PEGARULES.TB_MUNICIPIOS_OFERTAS set no_municipio= replace(no_municipio,'''''',chr(39))
A4: where no_municipio like '%''%';
A5: commit;
A7: select no_municipio from PEGARULES.TB_MUNICIPIOS_OFERTAS
A8: where no_municipio like '%''%';

Sheet Atual_2018-12-13
A1: UF | B1: NO_MUNICIPIO | C1: GRUPO_OFERTA | D1: GRUPO_PORTA_OCIOSAS | E1: DT_CRIACAO
A2: SP | B2: Indiana | E2: 43410
A3: SP | B3: Mesopolis | E3: 43410
A4: SP | B4: Parapua | E4: 43410
A5: SP | B5: Embauba | E5: 43410
A6: SP | B6: Lagoinha | E6: 43410
A7: SP | B7: Macedonia | E7: 43410
A8: SP | B8: Sao Francisco | E8: 43410
A9: SP | B9: Dolcinopolis | E9: 43410
A10: SP | B10: Sao Sebastiao da Grama | E10: 43410
A11: SP | B11: Vera Cruz | E11: 43410
A12: SP | B12: Cajati | E12: 43410
A13: SP | B13: Aspasia | E13: 43410
... A76: SP | B76: Flora Rica | E76: 43410
A77: PR | B77: Abatia | C77: CONEC LIGHT | E77: 43410
A78: PR | B78: Adrianopolis | C78: CONEC LIGHT | E78: 43410
A79: PR | B79: Agudos do Sul | C79: CONEC LIGHT | E79: 43410
A80: PR | B80: Almirante Tamandare | C80: CONEC LIGHT | E80: 43410
A81: PR | B81: Altamira do Parana | C81: CONEC LIGHT | E81: 43410
A82: PR | B82: Altonia | C82: CONEC LIGHT | D82: PO | E82: 43410
A83: PR | B83: Alto Parana | C83: CONEC LIGHT | E83: 43410
A84: PR | B84: Alto Piquiri | C84: CONEC LIGHT BL | D84: PO | E84: 43410
A85: PR | B85: Alvorada do Sul | C85: CONEC LIGHT | E85: 43410
A86: PR | B86: Amapora | C86: CONEC LIGHT | E86: 43410
A87: PR | B87: Ampere | C87: CONEC LIGHT | D87: PO | E87: 43410
A88: PR | B88: Anahy | C88: CONEC LIGHT | E88: 43410
A89: PR | B89: Andira | C89: CONEC LIGHT | D89: PO | E89: 43410
A90: PR | B90: angulo | C90: CONEC LIGHT | E90: 43410
A91: PR | B91: Antonina | C91: CONEC LIGHT | E91: 43410
A92: PR | B92: Antonio Olinto | C92: CONEC LIGHT | E92: 43410
A93: PR | B93: Apucarana | C93: CONEC LIGHT | E93: 43410
A94: PR | B94: Arapongas | C94: CONEC LIGHT | D94: PO | E94: 43410
A95: PR | B95: Arapoti | C95: CONEC LIGHT | D95: PO | E95: 43410
A96: PR | B96: Arapua | C96: CONEC LIGHT | E96: 43410
A97: PR | B97: Araruna | C97: CONEC LIGHT | E97: 43410
A98: PR | B98: Araucaria | C98: CONEC LIGHT | D98: PO | E98: 43410
A99: PR | B99: Ariranha do Ivai | C99: CONEC LIGHT | E99: 43410
A100: PR | B100: Assai | C100: CONEC LIGHT | D100: PO | E100: 43410
A101: PR | B101: Assis Chateaubriand | C101: CONEC LIGHT BL | D101: PO | E101: 43410
A102: PR | B102: Astorga | C102: CONEC LIGHT BL | E102: 43410
...

Sheet SQL
A1: pegarules.TB_MUNICIPIOS_OFERTAS
J2: De: | K2: '
A3: =_xlfn.CONCAT("SELECT * FROM ",A1) -> SELECT * FROM pegarules.TB_MUNICIPIOS_OFERTAS | J3: Para: | K3: ||chr(39)||'
A5: =_xlfn.CONCAT("DELETE FROM ",A1,";") -> DELETE FROM pegarules.TB_MUNICIPIOS_OFERTAS;
A6: COMMIT;

Sheet AtualProd_2018-12-13
A1: UF | B1: NO_MUNICIPIO | C1: GRUPO_OFERTA | D1: GRUPO_PORTA_OCIOSAS | E1: DT_CRIACAO
A2: ES | B2: Muqui | C2: CONEC LIGHT | E2: 43423
A3: ES | B3: Nova Venecia | C3: CONEC LIGHT | D3: PO | E3: 43423
A4: ES | B4: Pancas | C4: CONEC LIGHT | E4: 43423
A5: ES | B5: Pedro Canario | C5: CONEC LIGHT BL | E5: 43423
A6: ES | B6: Pinheiros | C6: CONEC LIGHT | E6: 43423
A7: ES | B7: Piuma | C7: CONEC LIGHT | E7: 43423
A8: ES | B8: Ponto Belo | C8: CONEC LIGHT BL | D8: PO | E8: 43423
A9: ES | B9: Presidente Kennedy | C9: CONEC LIGHT | E9: 43423
A10: ES | B10: Rio Bananal | C10: CONEC LIGHT | E10: 43423
A11: ES | B11: Rio Novo do Sul | C11: CONEC LIGHT | D11: PO | E11: 43423
A12: ES | B12: Santa Leopoldina | C12: CONEC LIGHT | D12: PO | E12: 43423
A13: ES | B13: Santa Maria de Jetiba | C13: CONEC LIGHT | E13: 43423
A14: ES | B14: Santa Teresa | C14: CONEC LIGHT | E14: 43423
A15: ES | B15: Sao Domingos do Norte | C15: CONEC LIGHT BL | D15: PO | E15: 43423
A16: ES | B16: Sao Gabriel da Palha | C16: CONEC LIGHT | E16: 43423
A17: ES | B17: Sao Jose do Calcado | C17: CONEC LIGHT BL | D17: PO | E17: 43423
A18: ES | B18: Sao Mateus | C18: CONEC LIGHT BL | D18: PO | E18: 43423
A19: ES | B19: Sao Roque do Canaa | C19: CONEC LIGHT | E19: 43423
A20: ES | B20: Serra | C20: CONEC LIGHT | E20: 43423
A21: ES | B21: Sooretama | C21: CONEC LIGHT | E21: 43423
A22: ES | B22: Vargem Alta | C22: CONEC LIGHT | E22: 43423
A23: ES | B23: Venda Nova do Imigrante | C23: CONEC LIGHT | E23: 43423
A24: ES | B24: Viana | C24: CONEC LIGHT | E24: 43423
A25: ES | B25: Vila Pavao | C25: CONEC LIGHT | E25: 43423
A26: ES | B26: Vila Valerio | C26: CONEC LIGHT | E26: 43423
A27: ES | B27: Vila Velha | C27: CONEC LIGHT | E27: 43423
A28: ES | B28: Vitoria | C28: CONEC LIGHT | E28: 43423
A29: RJ | B29: Angra dos Reis | C29: CONEC LIGHT | E29: 43423
A30: RJ | B30: Aperibe | C30: CONEC LIGHT | E30: 43423
A31: RJ | B31: Araruama | C31: CONEC LIGHT BL | D31: PO | E31: 43423
A32: RJ | B32: Areal | C32: CONEC LIGHT | E32: 43423
A33: RJ | B33: Armacao dos Buzios | C33: CONEC LIGHT | D33: PO | E33: 43423
A34: RJ | B34: Arraial do Cabo | C34: CONEC LIGHT | D34: PO | E34: 43423
A35: RJ | B35: Barra do Pirai | C35: CONEC LIGHT | D35: PO | E35: 43423
A36: RJ | B36: Barra Mansa | C36: CONEC LIGHT | D36: PO | E36: 43423
A37: RJ | B37: Belford Roxo | C37: CONEC LIGHT | D37: PO | E37: 43423
A38: RJ | B38: Bom Jardim | C38: CONEC LIGHT | E38: 43423
A39: RJ | B39: Bom Jesus do Itabapoana | C39: CONEC LIGHT BL | D39: PO | E39: 43423
A40: RJ | B40: Cabo Frio | C40: CONEC LIGHT | E40: 43423
...

Sheet Conectado Light
A1: UFMUNICÍPIO
A2: ACACRELANDIA | B2: Conectado Light | C2: =VLOOKUP(A2,'Exportar Planilha Final'!$C:$C,2,0) -> #N/A
A3: ACASSIS BRASIL | B3: Conectado Light | C3: =VLOOKUP(A3,'Exportar Planilha Final'!$C:$C,2,0) -> #N/A
A4: ACBRASILEIA | B4: Conectado Light | C4: =VLOOKUP(A4,'Exportar Planilha Final'!$C:$C,2,0) -> #N/A
A5: ACBUJARI | B5: Conectado Light | C5: =VLOOKUP(A5,'Exportar Planilha Final'!$C:$C,2,0) -> #N/A
A6: ACCAPIXABA | B6: Conectado Light | C6: =VLOOKUP(A6,'Exportar Planilha Final'!$C:$C,2,0) -> #N/A
A7: ACCRUZEIRO DO SUL | B7: Conectado Light | C7: =VLOOKUP(A7,'Exportar Planilha Final'!$C:$C,2,0) -> #N/A
A8: ACFEIJO | B8: Conectado Light | C8: =VLOOKUP(A8,'Exportar Planilha Final'!$C:$C,2,0) -> #N/A
A9: ACJORDAO | B9: Conectado Light | C9: =VLOOKUP(A9,'Exportar Planilha Final'!$C:$C,2,0) -> #N/A
A10: ACMANCIO LIMA | B10: Conectado Light | C10: =VLOOKUP(A10,'Exportar Planilha Final'!$C:$C,2,0) -> #N/A
A11: ACMANOEL URBANO | B11: Conectado Light | C11: =VLOOKUP(A11,'Exportar Planilha Final'!$C:$C,2,0) -> #N/A
A12: ACMARECHAL THAUMATURGO | B12: Conectado Light | C12: =VLOOKUP(A12,'Exportar Planilha Final'!$C:$C,2,0) -> #N/A
A13: ACPLACIDO DE CASTRO | B13: Conectado Light | C13: =VLOOKUP(A13,'Exportar Planilha Final'!$C:$C,2,0) -> #N/A
... A2752: SCZORTEA | B2752: Conectado Light | C2752: =VLOOKUP(A2752,'Exportar Planilha Final'!$C:$C,2,0) -> #N/A
